Workbook

Sheet Beosztás
A1: Tevékenység | B1: útmutató | T1: =IF(AZ8="január","2026.01.01",IF(AZ8="február","2026.02.01",IF(AZ8="március","2026.03.01",IF(AZ8="április","2026.04.01",IF(AZ8="május","2026.05.01",IF(AZ8="június","2026.06.01",IF(AZ8="július","2026.07.01",IF(AZ8="augusztus","2026.08.01",IF(AZ8="szeptember","2026.09.01",IF(AZ8="október","2026.10.01",IF(AZ8="november","2026.11.01",IF(AZ8="december","2026.12.01","")))))))))))) -> 2026.03.01 | U1: =T1+1 -> 46083 | V1: =U1+1 -> 46084 | W1: =V1+1 -> 46085 | X1: =W1+1 -> 46086 | Y1: =X1+1 -> 46087 | Z1: =Y1+1 -> 46088 | AA1: =Z1+1 -> 46089 | AB1: =AA1+1 -> 46090 | ... AX1: =AW1+1 -> 46112
T2: =WEEKDAY(T1) -> 1 | U2: =WEEKDAY(U1) -> 2 | V2: =WEEKDAY(V1) -> 3 | W2: =WEEKDAY(W1) -> 4 | X2: =WEEKDAY(X1) -> 5 | Y2: =WEEKDAY(Y1) -> 6 | Z2: =WEEKDAY(Z1) -> 7 | AA2: =WEEKDAY(AA1) -> 1 | ... AX2: =WEEKDAY(AX1) -> 3
T3: =IF(T2=1,"Vasárnap",IF(T2=2,"Hétfő",IF(T2=3,"Kedd",IF(T2=4,"Szerda",IF(T2=5,"Csütörtök",IF(T2=6,"Péntek",IF(T2=7,"Szombat",""))))))) -> Vasárnap | U3: =IF(U2=1,"Vasárnap",IF(U2=2,"Hétfő",IF(U2=3,"Kedd",IF(U2=4,"Szerda",IF(U2=5,"Csütörtök",IF(U2=6,"Péntek",IF(U2=7,"Szombat",""))))))) -> Hétfő | V3: =IF(V2=1,"Vasárnap",IF(V2=2,"Hétfő",IF(V2=3,"Kedd",IF(V2=4,"Szerda",IF(V2=5,"Csütörtök",IF(V2=6,"Péntek",IF(V2=7,"Szombat",""))))))) -> Kedd | W3: =IF(W2=1,"Vasárnap",IF(W2=2,"Hétfő",IF(W2=3,"Kedd",IF(W2=4,"Szerda",IF(W2=5,"Csütörtök",IF(W2=6,"Péntek",IF(W2=7,"Szombat",""))))))) -> Szerda | X3: =IF(X2=1,"Vasárnap",IF(X2=2,"Hétfő",IF(X2=3,"Kedd",IF(X2=4,"Szerda",IF(X2=5,"Csütörtök",IF(X2=6,"Péntek",IF(X2=7,"Szombat",""))))))) -> Csütörtök | Y3: =IF(Y2=1,"Vasárnap",IF(Y2=2,"Hétfő",IF(Y2=3,"Kedd",IF(Y2=4,"Szerda",IF(Y2=5,"Csütörtök",IF(Y2=6,"Péntek",IF(Y2=7,"Szombat",""))))))) -> Péntek | Z3: =IF(Z2=1,"Vasárnap",IF(Z2=2,"Hétfő",IF(Z2=3,"Kedd",IF(Z2=4,"Szerda",IF(Z2=5,"Csütörtök",IF(Z2=6,"Péntek",IF(Z2=7,"Szombat",""))))))) -> Szombat | AA3: =IF(AA2=1,"Vasárnap",IF(AA2=2,"Hétfő",IF(AA2=3,"Kedd",IF(AA2=4,"Szerda",IF(AA2=5,"Csütörtök",IF(AA2=6,"Péntek",IF(AA2=7,"Szombat",""))))))) -> Vasárnap | ... AX3: =IF(AX2=1,"Vasárnap",IF(AX2=2,"Hétfő",IF(AX2=3,"Kedd",IF(AX2=4,"Szerda",IF(AX2=5,"Csütörtök",IF(AX2=6,"Péntek",IF(AX2=7,"Szombat",""))))))) -> Kedd
A4: Angol levelezés | B4: A táblázat használata néhány lépésben: 1 Amennyiben szeretnél több infót a kollégákról a útmutató felett elhelyezett + gombbal tudod megtenni, 2, minden csoportvezető a saját fülén tudja kezelni a kollégák beosztását, 3 tevékenységenként is látható összesítő tábla az egyszerűbb átláthatóság érdekében | T4: =COUNTIF(T$43:T$388,$A4) -> 0 | U4: =COUNTIF(U$43:U$388,$A4) -> 1 | V4: =COUNTIF(V$43:V$388,$A4) -> 1 | W4: =COUNTIF(W$43:W$388,$A4) -> 1 | X4: =COUNTIF(X$43:X$388,$A4) -> 1 | Y4: =COUNTIF(Y$43:Y$388,$A4) -> 1 | Z4: =COUNTIF(Z$43:Z$388,$A4) -> 0 | AA4: =COUNTIF(AA$43:AA$388,$A4) -> 0 | ... AX4: =COUNTIF(AX$43:AX$388,$A4) -> 1
A5: angol SOS | T5: =COUNTIF(T$43:T$388,$A5) -> 0 | U5: =COUNTIF(U$43:U$388,$A5) -> 0 | V5: =COUNTIF(V$43:V$388,$A5) -> 0 | W5: =COUNTIF(W$43:W$388,$A5) -> 0 | X5: =COUNTIF(X$43:X$388,$A5) -> 0 | Y5: =COUNTIF(Y$43:Y$388,$A5) -> 0 | Z5: =COUNTIF(Z$43:Z$388,$A5) -> 0 | AA5: =COUNTIF(AA$43:AA$388,$A5) -> 0 | ... AX5: =COUNTIF(AX$43:AX$388,$A5) -> 0
A6: Magyar SOS | T6: =COUNTIF(T$43:T$388,$A6) -> 0 | U6: =COUNTIF(U$43:U$388,$A6) -> 0 | V6: =COUNTIF(V$43:V$388,$A6) -> 0 | W6: =COUNTIF(W$43:W$388,$A6) -> 0 | X6: =COUNTIF(X$43:X$388,$A6) -> 0 | Y6: =COUNTIF(Y$43:Y$388,$A6) -> 0 | Z6: =COUNTIF(Z$43:Z$388,$A6) -> 0 | AA6: =COUNTIF(AA$43:AA$388,$A6) -> 0 | ... AX6: =COUNTIF(AX$43:AX$388,$A6) -> 0
A7: Betanítás | T7: =COUNTIF(T$43:T$388,$A7) -> 0 | U7: =COUNTIF(U$43:U$388,$A7) -> 0 | V7: =COUNTIF(V$43:V$388,$A7) -> 0 | W7: =COUNTIF(W$43:W$388,$A7) -> 0 | X7: =COUNTIF(X$43:X$388,$A7) -> 0 | Y7: =COUNTIF(Y$43:Y$388,$A7) -> 0 | Z7: =COUNTIF(Z$43:Z$388,$A7) -> 0 | AA7: =COUNTIF(AA$43:AA$388,$A7) -> 0 | ... AX7: =COUNTIF(AX$43:AX$388,$A7) -> 0
A8: Betanulás | T8: =COUNTIF(T$43:T$388,$A8) -> 0 | U8: =COUNTIF(U$43:U$388,$A8) -> 0 | V8: =COUNTIF(V$43:V$388,$A8) -> 0 | W8: =COUNTIF(W$43:W$388,$A8) -> 0 | X8: =COUNTIF(X$43:X$388,$A8) -> 0 | Y8: =COUNTIF(Y$43:Y$388,$A8) -> 0 | Z8: =COUNTIF(Z$43:Z$388,$A8) -> 0 | AA8: =COUNTIF(AA$43:AA$388,$A8) -> 0 | ... AX8: =COUNTIF(AX$43:AX$388,$A8) -> 0 | AZ8: március
A9: CC | T9: =COUNTIF(T$43:T$388,$A9) -> 0 | U9: =COUNTIF(U$43:U$423,$A9) -> 0 | V9: =COUNTIF(V$43:V$388,$A9) -> 0 | W9: =COUNTIF(W$43:W$388,$A9) -> 0 | X9: =COUNTIF(X$43:X$388,$A9) -> 0 | Y9: =COUNTIF(Y$43:Y$388,$A9) -> 0 | Z9: =COUNTIF(Z$43:Z$388,$A9) -> 0 | AA9: =COUNTIF(AA$43:AA$388,$A9) -> 0 | AB9: =COUNTIF(AB$43:AB$388,$A9) -> 0 | AC9: =COUNTIF(AC$43:AC$388,$A9) -> 0 | ... AX9: =COUNTIF(AX$43:AX$388,$A9) -> 0
A10: CC angol | T10: =COUNTIF(T$43:T$388,$A10) -> 0 | U10: =COUNTIF(U$43:U$388,$A10) -> 0 | V10: =COUNTIF(V$43:V$388,$A10) -> 0 | W10: =COUNTIF(W$43:W$388,$A10) -> 0 | X10: =COUNTIF(X$43:X$388,$A10) -> 0 | Y10: =COUNTIF(Y$43:Y$388,$A10) -> 0 | Z10: =COUNTIF(Z$43:Z$388,$A10) -> 0 | AA10: =COUNTIF(AA$43:AA$388,$A10) -> 0 | ... AX10: =COUNTIF(AX$43:AX$388,$A10) -> 0
A11: CC német | T11: =COUNTIF(T$43:T$388,$A11) -> 0 | U11: =COUNTIF(U$43:U$388,$A11) -> 0 | V11: =COUNTIF(V$43:V$388,$A11) -> 0 | W11: =COUNTIF(W$43:W$388,$A11) -> 0 | X11: =COUNTIF(X$43:X$388,$A11) -> 0 | Y11: =COUNTIF(Y$43:Y$388,$A11) -> 0 | Z11: =COUNTIF(Z$43:Z$388,$A11) -> 0 | AA11: =COUNTIF(AA$43:AA$388,$A11) -> 0 | ... AX11: =COUNTIF(AX$43:AX$388,$A11) -> 0
A12: CC NM | T12: =COUNTIF(T$43:T$388,$A12) -> 0 | U12: =COUNTIF(U$43:U$388,$A12) -> 0 | V12: =COUNTIF(V$43:V$388,$A12) -> 0 | W12: =COUNTIF(W$43:W$388,$A12) -> 0 | X12: =COUNTIF(X$43:X$388,$A12) -> 0 | Y12: =COUNTIF(Y$43:Y$388,$A12) -> 0 | Z12: =COUNTIF(Z$43:Z$388,$A12) -> 0 | AA12: =COUNTIF(AA$43:AA$388,$A12) -> 0 | ... AX12: =COUNTIF(AX$43:AX$388,$A12) -> 0
A13: e-csoportos | T13: =COUNTIF(T$43:T$388,$A13) -> 0 | U13: =COUNTIF(U$43:U$388,$A13) -> 0 | V13: =COUNTIF(V$43:V$388,$A13) -> 0 | W13: =COUNTIF(W$43:W$388,$A13) -> 0 | X13: =COUNTIF(X$43:X$388,$A13) -> 0 | Y13: =COUNTIF(Y$43:Y$388,$A13) -> 0 | Z13: =COUNTIF(Z$43:Z$388,$A13) -> 0 | AA13: =COUNTIF(AA$43:AA$388,$A13) -> 0 | ... AX13: =COUNTIF(AX$43:AX$388,$A13) -> 0
A14: Egyéb ügyintézés | T14: =COUNTIF(T$43:T$388,$A14) -> 0 | U14: =COUNTIF(U$43:U$388,$A14) -> 0 | V14: =COUNTIF(V$43:V$388,$A14) -> 0 | W14: =COUNTIF(W$43:W$388,$A14) -> 0 | X14: =COUNTIF(X$43:X$388,$A14) -> 0 | Y14: =COUNTIF(Y$43:Y$388,$A14) -> 0 | Z14: =COUNTIF(Z$43:Z$388,$A14) -> 0 | AA14: =COUNTIF(AA$43:AA$388,$A14) -> 0 | ... AX14: =COUNTIF(AX$43:AX$388,$A14) -> 0
A15: E-ÜSZI | T15: =COUNTIF(T$43:T$388,$A15) -> 0 | U15: =COUNTIF(U$43:U$388,$A15) -> 1 | V15: =COUNTIF(V$43:V$388,$A15) -> 1 | W15: =COUNTIF(W$43:W$388,$A15) -> 1 | X15: =COUNTIF(X$43:X$388,$A15) -> 1 | Y15: =COUNTIF(Y$43:Y$388,$A15) -> 1 | Z15: =COUNTIF(Z$43:Z$388,$A15) -> 0 | AA15: =COUNTIF(AA$43:AA$388,$A15) -> 0 | ... AX15: =COUNTIF(AX$43:AX$388,$A15) -> 1
A16: HUGO | T16: =COUNTIF(T$43:T$388,$A16) -> 0 | U16: =COUNTIF(U$43:U$388,$A16) -> 2 | V16: =COUNTIF(V$43:V$388,$A16) -> 2 | W16: =COUNTIF(W$43:W$388,$A16) -> 2 | X16: =COUNTIF(X$43:X$388,$A16) -> 2 | Y16: =COUNTIF(Y$43:Y$388,$A16) -> 2 | Z16: =COUNTIF(Z$43:Z$388,$A16) -> 0 | AA16: =COUNTIF(AA$43:AA$388,$A16) -> 0 | ... AX16: =COUNTIF(AX$43:AX$388,$A16) -> 1
A17: HUGO (@) | T17: =COUNTIF(T$43:T$388,$A17) -> 0 | U17: =COUNTIF(U$43:U$388,$A17) -> 1 | V17: =COUNTIF(V$43:V$388,$A17) -> 1 | W17: =COUNTIF(W$43:W$388,$A17) -> 1 | X17: =COUNTIF(X$43:X$388,$A17) -> 1 | Y17: =COUNTIF(Y$43:Y$388,$A17) -> 1 | Z17: =COUNTIF(Z$43:Z$388,$A17) -> 0 | AA17: =COUNTIF(AA$43:AA$388,$A17) -> 0 | ... AX17: =COUNTIF(AX$43:AX$388,$A17) -> 1
A18: Iktatás | T18: =COUNTIF(T$43:T$423,$A18) -> 0 | U18: =COUNTIF(U$43:U$423,$A18) -> 0 | V18: =COUNTIF(V$43:V$423,$A18) -> 0 | W18: =COUNTIF(W$43:W$423,$A18) -> 0 | X18: =COUNTIF(X$43:X$423,$A18) -> 0 | Y18: =COUNTIF(Y$43:Y$423,$A18) -> 1 | Z18: =COUNTIF(Z$43:Z$423,$A18) -> 0 | AA18: =COUNTIF(AA$43:AA$423,$A18) -> 0 | ... AX18: =COUNTIF(AX$43:AX$423,$A18) -> 0
A19: Jelölő (@) | T19: =COUNTIF(T$43:T$388,$A19) -> 0 | U19: =COUNTIF(U$43:U$388,$A19) -> 0 | V19: =COUNTIF(V$43:V$388,$A19) -> 0 | W19: =COUNTIF(W$43:W$388,$A19) -> 0 | X19: =COUNTIF(X$43:X$388,$A19) -> 0 | Y19: =COUNTIF(Y$43:Y$388,$A19) -> 0 | Z19: =COUNTIF(Z$43:Z$388,$A19) -> 0 | AA19: =COUNTIF(AA$43:AA$388,$A19) -> 0 | ... AX19: =COUNTIF(AX$43:AX$388,$A19) -> 0
A20: Jogsegély levelezés | T20: =COUNTIF(T$43:T$388,$A20) -> 0 | U20: =COUNTIF(U$43:U$388,$A20) -> 3 | V20: =COUNTIF(V$43:V$388,$A20) -> 2 | W20: =COUNTIF(W$43:W$388,$A20) -> 3 | X20: =COUNTIF(X$43:X$388,$A20) -> 2 | Y20: =COUNTIF(Y$43:Y$388,$A20) -> 3 | Z20: =COUNTIF(Z$43:Z$388,$A20) -> 0 | AA20: =COUNTIF(AA$43:AA$388,$A20) -> 0 | ... AX20: =COUNTIF(AX$43:AX$388,$A20) -> 2
A21: Jogsegély szignálás | T21: =COUNTIF(T$43:T$388,$A21) -> 0 | U21: =COUNTIF(U$43:U$388,$A21) -> 1 | V21: =COUNTIF(V$43:V$388,$A21) -> 1 | W21: =COUNTIF(W$43:W$388,$A21) -> 1 | X21: =COUNTIF(X$43:X$388,$A21) -> 1 | Y21: =COUNTIF(Y$43:Y$388,$A21) -> 0 | Z21: =COUNTIF(Z$43:Z$388,$A21) -> 0 | AA21: =COUNTIF(AA$43:AA$388,$A21) -> 0 | ... AX21: =COUNTIF(AX$43:AX$388,$A21) -> 1
A22: KPLLC ügyintézés | T22: =COUNTIF(T$43:T$388,$A22) -> 0 | U22: =COUNTIF(U$43:U$388,$A22) -> 0 | V22: =COUNTIF(V$43:V$388,$A22) -> 0 | W22: =COUNTIF(W$43:W$388,$A22) -> 0 | X22: =COUNTIF(X$43:X$388,$A22) -> 0 | Y22: =COUNTIF(Y$43:Y$388,$A22) -> 0 | Z22: =COUNTIF(Z$43:Z$388,$A22) -> 0 | AA22: =COUNTIF(AA$43:AA$388,$A22) -> 0 | ... AX22: =COUNTIF(AX$43:AX$388,$A22) -> 0
A23: Külföldi irodák | T23: =COUNTIF(T$43:T$388,$A23) -> 0 | U23: =COUNTIF(U$43:U$388,$A23) -> 4 | V23: =COUNTIF(V$43:V$388,$A23) -> 4 | W23: =COUNTIF(W$43:W$388,$A23) -> 4 | X23: =COUNTIF(X$43:X$388,$A23) -> 4 | Y23: =COUNTIF(Y$43:Y$388,$A23) -> 4 | Z23: =COUNTIF(Z$43:Z$388,$A23) -> 0 | AA23: =COUNTIF(AA$43:AA$388,$A23) -> 0 | ... AX23: =COUNTIF(AX$43:AX$388,$A23) -> 4
A24: Levelezés EM | T24: =COUNTIF(T$43:T$388,$A24) -> 0 | U24: =COUNTIF(U$43:U$388,$A24) -> 1 | V24: =COUNTIF(V$43:V$388,$A24) -> 2 | W24: =COUNTIF(W$43:W$388,$A24) -> 2 | X24: =COUNTIF(X$43:X$388,$A24) -> 3 | Y24: =COUNTIF(Y$43:Y$388,$A24) -> 0 | Z24: =COUNTIF(Z$43:Z$388,$A24) -> 0 | AA24: =COUNTIF(AA$43:AA$388,$A24) -> 0 | ... AX24: =COUNTIF(AX$43:AX$388,$A24) -> 3
A25: ÜSZI + Levelezés | T25: =COUNTIF(T$43:T$388,$A25) -> 0 | U25: =COUNTIF(U$43:U$388,$A25) -> 0 | V25: =COUNTIF(V$43:V$388,$A25) -> 0 | W25: =COUNTIF(W$43:W$388,$A25) -> 0 | X25: =COUNTIF(X$43:X$388,$A25) -> 0 | Y25: =COUNTIF(Y$43:Y$388,$A25) -> 0 | Z25: =COUNTIF(Z$43:Z$388,$A25) -> 0 | AA25: =COUNTIF(AA$43:AA$388,$A25) -> 0 | ... AX25: =COUNTIF(AX$43:AX$388,$A25) -> 0
A26: Levélírás | T26: =COUNTIF(T$43:T$423,$A26) -> 0 | U26: =COUNTIF(U$43:U$423,$A26) -> 16 | V26: =COUNTIF(V$43:V$423,$A26) -> 18 | W26: =COUNTIF(W$43:W$423,$A26) -> 15 | X26: =COUNTIF(X$43:X$423,$A26) -> 15 | Y26: =COUNTIF(Y$43:Y$423,$A26) -> 16 | Z26: =COUNTIF(Z$43:Z$423,$A26) -> 0 | AA26: =COUNTIF(AA$43:AA$423,$A26) -> 0 | ... AX26: =COUNTIF(AX$43:AX$423,$A26) -> 17
A27: Panaszkezelés | T27: =COUNTIF(T$43:T$388,$A27) -> 0 | U27: =COUNTIF(U$43:U$388,$A27) -> 0 | V27: =COUNTIF(V$43:V$388,$A27) -> 0 | W27: =COUNTIF(W$43:W$388,$A27) -> 0 | X27: =COUNTIF(X$43:X$388,$A27) -> 0 | Y27: =COUNTIF(Y$43:Y$388,$A27) -> 0 | Z27: =COUNTIF(Z$43:Z$388,$A27) -> 0 | AA27: =COUNTIF(AA$43:AA$388,$A27) -> 0 | ... AX27: =COUNTIF(AX$43:AX$388,$A27) -> 0
A28: Tesztelés | T28: =COUNTIF(T$43:T$388,$A28) -> 0 | U28: =COUNTIF(U$43:U$388,$A28) -> 0 | V28: =COUNTIF(V$43:V$388,$A28) -> 0 | W28: =COUNTIF(W$43:W$388,$A28) -> 0 | X28: =COUNTIF(X$43:X$388,$A28) -> 0 | Y28: =COUNTIF(Y$43:Y$388,$A28) -> 0 | Z28: =COUNTIF(Z$43:Z$388,$A28) -> 0 | AA28: =COUNTIF(AA$43:AA$388,$A28) -> 0 | ... AX28: =COUNTIF(AX$43:AX$388,$A28) -> 0
A29: ÜSZI | T29: =COUNTIF(T$43:T$388,$A29) -> 0 | U29: =COUNTIF(U$43:U$388,$A29) -> 22 | V29: =COUNTIF(V$43:V$388,$A29) -> 22 | W29: =COUNTIF(W$43:W$388,$A29) -> 23 | X29: =COUNTIF(X$43:X$388,$A29) -> 23 | Y29: =COUNTIF(Y$43:Y$388,$A29) -> 23 | Z29: =COUNTIF(Z$43:Z$388,$A29) -> 0 | AA29: =COUNTIF(AA$43:AA$388,$A29) -> 0 | ... AX29: =COUNTIF(AX$43:AX$388,$A29) -> 21
A30: Video | T30: =COUNTIF(T$43:T$388,$A30)+COUNTIF(T$43:T$388,Admin_legördülő!$B29)+COUNTIF(T$43:T$388,Admin_legördülő!$B30) -> 0 | U30: =COUNTIF(U$43:U$388,$A30)+COUNTIF(U$43:U$388,Admin_legördülő!$B29)+COUNTIF(U$43:U$388,Admin_legördülő!$B30) -> 12 | V30: =COUNTIF(V$43:V$388,$A30)+COUNTIF(V$43:V$388,Admin_legördülő!$B29)+COUNTIF(V$43:V$388,Admin_legördülő!$B30) -> 12 | W30: =COUNTIF(W$43:W$388,$A30)+COUNTIF(W$43:W$388,Admin_legördülő!$B29)+COUNTIF(W$43:W$388,Admin_legördülő!$B30) -> 12 | X30: =COUNTIF(X$43:X$388,$A30)+COUNTIF(X$43:X$388,Admin_legördülő!$B29)+COUNTIF(X$43:X$388,Admin_legördülő!$B30) -> 12 | Y30: =COUNTIF(Y$43:Y$388,$A30)+COUNTIF(Y$43:Y$388,Admin_legördülő!$B29)+COUNTIF(Y$43:Y$388,Admin_legördülő!$B30) -> 10 | Z30: =COUNTIF(Z$43:Z$388,$A30)+COUNTIF(Z$43:Z$388,Admin_legördülő!$B29)+COUNTIF(Z$43:Z$388,Admin_legördülő!$B30) -> 0 | AA30: =COUNTIF(AA$43:AA$388,$A30)+COUNTIF(AA$43:AA$388,Admin_legördülő!$B29)+COUNTIF(AA$43:AA$388,Admin_legördülő!$B30) -> 0 | ... AI30: =COUNTIF(AI$43:AI$388,$A30)+COUNTIF(AI$43:AI$388,Admin_legördülő!$B29)+COUNTIF(AI$43:AI$388,Admin_legördülő!$B30) -> 14 | AJ30: =COUNTIF(AJ$43:AJ$388,$A30) -> 0 | AK30: =COUNTIF(AK$43:AK$388,$A30)+COUNTIF(AK$43:AK$388,Admin_legördülő!$B29)+COUNTIF(AK$43:AK$388,Admin_legördülő!$B30) -> 14 | AL30: =COUNTIF(AL$43:AL$388,$A30)+COUNTIF(AL$43:AL$388,Admin_legördülő!$B29)+COUNTIF(AL$43:AL$388,Admin_legördülő!$B30) -> 14 | AM30: =COUNTIF(AM$43:AM$388,$A30)+COUNTIF(AM$43:AM$388,Admin_legördülő!$B29)+COUNTIF(AM$43:AM$388,Admin_legördülő!$B30) -> 14 | AN30: =COUNTIF(AN$43:AN$388,$A30)+COUNTIF(AN$43:AN$388,Admin_legördülő!$B29)+COUNTIF(AN$43:AN$388,Admin_legördülő!$B30) -> 0 | AO30: =COUNTIF(AO$43:AO$388,$A30)+COUNTIF(AO$43:AO$388,Admin_legördülő!$B29)+COUNTIF(AO$43:AO$388,Admin_legördülő!$B30) -> 0 | AP30: =COUNTIF(AP$43:AP$388,$A30)+COUNTIF(AP$43:AP$388,Admin_legördülő!$B29)+COUNTIF(AP$43:AP$388,Admin_legördülő!$B30) -> 13 | AQ30: =COUNTIF(AQ$43:AQ$388,$A30)+COUNTIF(AQ$43:AQ$388,Admin_legördülő!$B29)+COUNTIF(AQ$43:AQ$388,Admin_legördülő!$B30) -> 13 | AR30: =COUNTIF(AR$43:AR$388,$A30)+COUNTIF(AR$43:AR$388,Admin_legördülő!$B29)+COUNTIF(AR$43:AR$388,Admin_legördülő!$B30) -> 13 | ... AX30: =COUNTIF(AX$43:AX$388,$A30)+COUNTIF(AX$43:AX$388,Admin_legördülő!$B29)+COUNTIF(AX$43:AX$388,Admin_legördülő!$B30) -> 12
A31: SZ | T31: =COUNTIF(T$43:T$388,$A31) -> 0 | U31: =COUNTIF(U$43:U$388,$A31) -> 3 | V31: =COUNTIF(V$43:V$388,$A31) -> 1 | W31: =COUNTIF(W$43:W$388,$A31) -> 2 | X31: =COUNTIF(X$43:X$388,$A31) -> 2 | Y31: =COUNTIF(Y$43:Y$388,$A31) -> 4 | Z31: =COUNTIF(Z$43:Z$388,$A31) -> 0 | AA31: =COUNTIF(AA$43:AA$388,$A31) -> 0 | ... AX31: =COUNTIF(AX$43:AX$388,$A31) -> 3
A32: P | T32: =COUNTIF(T$43:T$388,$A32) -> 11 | U32: =COUNTIF(U$43:U$388,$A32) -> 0 | V32: =COUNTIF(V$43:V$388,$A32) -> 0 | W32: =COUNTIF(W$43:W$388,$A32) -> 0 | X32: =COUNTIF(X$43:X$388,$A32) -> 0 | Y32: =COUNTIF(Y$43:Y$388,$A32) -> 0 | Z32: =COUNTIF(Z$43:Z$388,$A32) -> 11 | AA32: =COUNTIF(AA$43:AA$388,$A32) -> 11 | ... AX32: =COUNTIF(AX$43:AX$388,$A32) -> 0
A33: B | T33: =COUNTIF(T$43:T$388,$A33) -> 0 | U33: =COUNTIF(U$43:U$388,$A33) -> 3 | V33: =COUNTIF(V$43:V$388,$A33) -> 3 | W33: =COUNTIF(W$43:W$388,$A33) -> 3 | X33: =COUNTIF(X$43:X$388,$A33) -> 3 | Y33: =COUNTIF(Y$43:Y$388,$A33) -> 3 | Z33: =COUNTIF(Z$43:Z$388,$A33) -> 0 | AA33: =COUNTIF(AA$43:AA$388,$A33) -> 0 | ... AX33: =COUNTIF(AX$43:AX$388,$A33) -> 3
A34: Oktatás - külső | T34: =COUNTIF(T$43:T$388,$A34) -> 0 | U34: =COUNTIF(U$43:U$388,$A34) -> 0 | V34: =COUNTIF(V$43:V$388,$A34) -> 0 | W34: =COUNTIF(W$43:W$388,$A34) -> 0 | X34: =COUNTIF(X$43:X$388,$A34) -> 0 | Y34: =COUNTIF(Y$43:Y$388,$A34) -> 0 | Z34: =COUNTIF(Z$43:Z$388,$A34) -> 0 | AA34: =COUNTIF(AA$43:AA$388,$A34) -> 0 | ... AX34: =COUNTIF(AX$43:AX$388,$A34) -> 0
A35: Elismerések napja | T35: =COUNTIF(T$43:T$388,$A35) -> 0 | U35: =COUNTIF(U$43:U$388,$A35) -> 0 | V35: =COUNTIF(V$43:V$388,$A35) -> 0 | W35: =COUNTIF(W$43:W$388,$A35) -> 0 | X35: =COUNTIF(X$43:X$388,$A35) -> 0 | Y35: =COUNTIF(Y$43:Y$388,$A35) -> 0 | Z35: =COUNTIF(Z$43:Z$388,$A35) -> 0 | AA35: =COUNTIF(AA$43:AA$388,$A35) -> 0 | ... AX35: =COUNTIF(AX$43:AX$388,$A35) -> 0
A36: HIF - Levelezés | T36: =COUNTIF(T$43:T$397,$A36) -> 0 | U36: =COUNTIF(U$43:U$397,$A36) -> 0 | V36: =COUNTIF(V$43:V$397,$A36) -> 0 | W36: =COUNTIF(W$43:W$397,$A36) -> 0 | X36: =COUNTIF(X$43:X$397,$A36) -> 0 | Y36: =COUNTIF(Y$43:Y$397,$A36) -> 0 | Z36: =COUNTIF(Z$43:Z$397,$A36) -> 0 | AA36: =COUNTIF(AA$43:AA$388,$A36) -> 0 | AB36: =COUNTIF(AB$43:AB$397,$A36) -> 0 | AC36: =COUNTIF(AC$43:AC$397,$A36) -> 0 | AD36: =COUNTIF(AD$43:AD$397,$A36) -> 0 | AE36: =COUNTIF(AE$43:AE$397,$A36) -> 0 | AF36: =COUNTIF(AF$43:AF$397,$A36) -> 0 | AG36: =COUNTIF(AG$43:AG$397,$A36) -> 0 | AH36: =COUNTIF(AH$43:AH$397,$A36) -> 0 | AI36: =COUNTIF(AI$43:AI$423,$A36) -> 0 | AJ36: =COUNTIF(AJ$43:AJ$423,$A36) -> 0 | AK36: =COUNTIF(AK$43:AK$423,$A36) -> 0 | AL36: =COUNTIF(AL$43:AL$423,$A36) -> 0 | AM36: =COUNTIF(AM$43:AM$423,$A36) -> 0 | AN36: =COUNTIF(AN$43:AN$397,$A36) -> 0 | AO36: =COUNTIF(AO$43:AO$397,$A36) -> 0 | AP36: =COUNTIF(AP$43:AP$397,$A36) -> 0 | AQ36: =COUNTIF(AQ$43:AQ$397,$A36) -> 0 | AR36: =COUNTIF(AR$43:AR$397,$A36) -> 0 | AS36: =COUNTIF(AS$43:AS$397,$A36) -> 0 | AT36: =COUNTIF(AT$43:AT$397,$A36) -> 0 | AU36: =COUNTIF(AU$43:AU$397,$A36) -> 0 | AV36: =COUNTIF(AV$43:AV$397,$A36) -> 0 | AW36: =COUNTIF(AW$43:AW$423,$A36) -> 0 | AX36: =COUNTIF(AX$43:AX$423,$A36) -> 0
A37: HIF - Iktatás | T37: =COUNTIF(T$43:T$397,$A37) -> 0 | U37: =COUNTIF(U$43:U$397,$A37) -> 0 | V37: =COUNTIF(V$43:V$397,$A37) -> 0 | W37: =COUNTIF(W$43:W$397,$A37) -> 0 | X37: =COUNTIF(X$43:X$397,$A37) -> 0 | Y37: =COUNTIF(Y$43:Y$397,$A37) -> 0 | Z37: =COUNTIF(Z$43:Z$397,$A37) -> 0 | AB37: =COUNTIF(AB$43:AB$397,$A37) -> 0 | AC37: =COUNTIF(AC$43:AC$397,$A37) -> 0 | AD37: =COUNTIF(AD$43:AD$397,$A37) -> 0 | AE37: =COUNTIF(AE$43:AE$397,$A37) -> 0 | AF37: =COUNTIF(AF$43:AF$397,$A37) -> 0 | AG37: =COUNTIF(AG$43:AG$397,$A37) -> 0 | AH37: =COUNTIF(AH$43:AH$397,$A37) -> 0 | AI37: =COUNTIF(AI$43:AI$423,$A37) -> 0 | AJ37: =COUNTIF(AJ$43:AJ$423,$A37) -> 0 | AK37: =COUNTIF(AK$43:AK$423,$A37) -> 0 | AL37: =COUNTIF(AL$43:AL$423,$A37) -> 0 | AM37: =COUNTIF(AM$43:AM$423,$A37) -> 0 | AN37: =COUNTIF(AN$43:AN$397,$A37) -> 0 | AO37: =COUNTIF(AO$43:AO$397,$A37) -> 0 | AP37: =COUNTIF(AP$43:AP$397,$A37) -> 0 | AQ37: =COUNTIF(AQ$43:AQ$397,$A37) -> 0 | AR37: =COUNTIF(AR$43:AR$397,$A37) -> 0 | AS37: =COUNTIF(AS$43:AS$397,$A37) -> 0 | AT37: =COUNTIF(AT$43:AT$397,$A37) -> 0 | AU37: =COUNTIF(AU$43:AU$397,$A37) -> 0 | AV37: =COUNTIF(AV$43:AV$397,$A37) -> 0 | AW37: =COUNTIF(AW$43:AW$423,$A37) -> 0 | AX37: =COUNTIF(AX$43:AX$423,$A37) -> 0
A38: HIF - CC | T38: =COUNTIF(T$43:T$397,$A38) -> 0 | U38: =COUNTIF(U$43:U$397,$A38) -> 0 | V38: =COUNTIF(V$43:V$397,$A38) -> 0 | W38: =COUNTIF(W$43:W$397,$A38) -> 0 | X38: =COUNTIF(X$43:X$397,$A38) -> 0 | Y38: =COUNTIF(Y$43:Y$397,$A38) -> 0 | Z38: =COUNTIF(Z$43:Z$397,$A38) -> 0 | AA38: =COUNTIF(AA$43:AA$388,$A38) -> 0 | AB38: =COUNTIF(AB$43:AB$397,$A38) -> 0 | AC38: =COUNTIF(AC$43:AC$397,$A38) -> 0 | AD38: =COUNTIF(AD$43:AD$397,$A38) -> 0 | AE38: =COUNTIF(AE$43:AE$397,$A38) -> 0 | AF38: =COUNTIF(AF$43:AF$397,$A38) -> 0 | AG38: =COUNTIF(AG$43:AG$397,$A38) -> 0 | AH38: =COUNTIF(AH$43:AH$397,$A38) -> 0 | AI38: =COUNTIF(AI$43:AI$423,$A38) -> 0 | AJ38: =COUNTIF(AJ$43:AJ$423,$A38) -> 0 | AK38: =COUNTIF(AK$43:AK$423,$A38) -> 0 | AL38: =COUNTIF(AL$43:AL$423,$A38) -> 0 | AM38: =COUNTIF(AM$43:AM$423,$A38) -> 0 | AN38: =COUNTIF(AN$43:AN$397,$A38) -> 0 | AO38: =COUNTIF(AO$43:AO$397,$A38) -> 0 | AP38: =COUNTIF(AP$43:AP$397,$A38) -> 0 | AQ38: =COUNTIF(AQ$43:AQ$397,$A38) -> 0 | AR38: =COUNTIF(AR$43:AR$397,$A38) -> 0 | AS38: =COUNTIF(AS$43:AS$397,$A38) -> 0 | AT38: =COUNTIF(AT$43:AT$397,$A38) -> 0 | AU38: =COUNTIF(AU$43:AU$397,$A38) -> 0 | AV38: =COUNTIF(AV$43:AV$397,$A38) -> 0 | AW38: =COUNTIF(AW$43:AW$423,$A38) -> 0 | AX38: =COUNTIF(AX$43:AX$423,$A38) -> 0
A39: Nem dolgozik | T39: =SUM(T31:T33) -> 11 | U39: =SUM(U31:U33) -> 6 | V39: =SUM(V31:V33) -> 4 | W39: =SUM(W31:W33) -> 5 | X39: =SUM(X31:X33) -> 5 | Y39: =SUM(Y31:Y33) -> 7 | Z39: =SUM(Z31:Z33) -> 11 | AA39: =SUM(AA31:AA33) -> 11 | ... AX39: =SUM(AX31:AX33) -> 6
A41: Jóváhagyó
...

Sheet Mátrix
F1: Telefon | J1: Videochat | K1: Személyes | N1: Levélírás | AC1: Nyelvtudás
A2: Név | B2: Csop. Vez | C2: Terület | D2: Csoport | E2: Státusz | F2: CC | G2: CC - Angol | H2: CC - Német | I2: CC - NMF | J2: Videochat | K2: Személyes ügyfélszolgálat | L2: Csoportos megrendelők feldolgozása - elektronikus átvétel | M2: Szolgáltatási díj számla tisztázás (1375) | N2: @Jelölő | O2: Iktatás | P2: Levél - UD (HUGO) | Q2: Levél - HD | R2: Levél - eÜSZI | S2: Iktatás - Jogsegély | T2: Levél - Jogsegély | U2: Szignálás - Jogsegély | V2: Postázás - Jogsegély | W2: Levél - Angol | X2: KPLLC ügyintézés | Y2: Díjmentes adatbázis kezelése | Z2: Külföldi irodák | AA2: Panaszkezelés (besegítéshez) | AB2: Napi terelés összesítő tábla töltés | AC2: Angol | AD2: Német | AE2: Egyéb
A3: ='Budapesti csoport'!A5 -> Barna Emőke | B3: ='Budapesti csoport'!B5 -> SZÜTS KATALIN | C3: ='Budapesti csoport'!C5 -> M3 | D3: ='Budapesti csoport'!D5 -> Budapesti | E3: ='Budapesti csoport'!E5 -> aktív | J3: BF | K3: =[1]mátrix!J50 -> 1 | O3: =[1]mátrix!N50 -> H1 | Q3: =[1]mátrix!P50 -> H1 | AC3: =IF(VLOOKUP(A3,Beosztás!A:F,6,0)="Igen","Igen","") | AD3: =IF(VLOOKUP(A3,Beosztás!A:G,7,0)="igen","igen","")
A4: ='Budapesti csoport'!A6 -> Basa Istvánné | B4: ='Budapesti csoport'!B6 -> SZÜTS KATALIN | C4: ='Budapesti csoport'!C6 -> M3 | D4: ='Budapesti csoport'!D6 -> Budapesti | E4: ='Budapesti csoport'!E6 -> aktív | F4: =[1]mátrix!E51 -> H1 | J4: =[1]mátrix!I51 -> H1 | K4: =[1]mátrix!J51 -> 1 | O4: =[1]mátrix!N51 -> H1 | Q4: =[1]mátrix!P51 -> H1 | T4: =[1]mátrix!S51 -> H2 | Z4: =[1]mátrix!Y51 -> H1 | AA4: =[1]mátrix!Z51 -> H1 | AC4: =IF(VLOOKUP(A4,Beosztás!A:F,6,0)="Igen","Igen","") | AD4: =IF(VLOOKUP(A4,Beosztás!A:G,7,0)="igen","igen","")
A5: ='Budapesti csoport'!A7 -> Bottyáni Vanda | B5: ='Budapesti csoport'!B7 -> SZÜTS KATALIN | C5: ='Budapesti csoport'!C7 -> M3 | D5: ='Budapesti csoport'!D7 -> Budapesti | E5: ='Budapesti csoport'!E7 -> aktív | F5: =[1]mátrix!E52 -> H1 | J5: =[1]mátrix!I52 -> H1 | K5: =[1]mátrix!J52 -> 1 | O5: =[1]mátrix!N52 -> H1 | Q5: =[1]mátrix!P52 -> H1 | T5: =[1]mátrix!S52 -> H2 | Z5: =[1]mátrix!Y52 -> H1 | AA5: =[1]mátrix!Z52 -> H1 | AC5: =IF(VLOOKUP(A5,Beosztás!A:F,6,0)="Igen","Igen","") | AD5: =IF(VLOOKUP(A5,Beosztás!A:G,7,0)="igen","igen","")
A6: ='Budapesti csoport'!A8 -> Egresiné Várhelyi Eszter Fanni | B6: ='Budapesti csoport'!B8 -> SZÜTS KATALIN | C6: ='Budapesti csoport'!C8 -> M3 | D6: ='Budapesti csoport'!D8 -> Budapesti | E6: ='Budapesti csoport'!E8 -> aktív | J6: BF | K6: =[1]mátrix!J53 -> 1 | O6: =[1]mátrix!N53 -> H1 | Q6: =[1]mátrix!P53 -> H1 | W6: BF | AC6: =IF(VLOOKUP(A6,Beosztás!A:F,6,0)="Igen","Igen","") -> Igen | AD6: =IF(VLOOKUP(A6,Beosztás!A:G,7,0)="igen","igen","")
A7: ='Budapesti csoport'!A9 -> Fejér Zsuzsanna | B7: ='Budapesti csoport'!B9 -> SZÜTS KATALIN | C7: ='Budapesti csoport'!C9 -> M3 | D7: ='Budapesti csoport'!D9 -> Budapesti | E7: ='Budapesti csoport'!E9 -> aktív | K7: =[1]mátrix!J54 -> 1 | AC7: =IF(VLOOKUP(A7,Beosztás!A:F,6,0)="Igen","Igen","") | AD7: =IF(VLOOKUP(A7,Beosztás!A:G,7,0)="igen","igen","")
A8: ='Budapesti csoport'!A10 -> Horváth Julianna | B8: ='Budapesti csoport'!B10 -> SZÜTS KATALIN | C8: ='Budapesti csoport'!C10 -> M3 | D8: ='Budapesti csoport'!D10 -> Budapesti | E8: ='Budapesti csoport'!E10 -> aktív | J8: =[1]mátrix!I55 -> KV | K8: =[1]mátrix!J55 -> 1 | O8: =[1]mátrix!N55 -> H1 | Q8: =[1]mátrix!P55 -> H1 | AC8: =IF(VLOOKUP(A8,Beosztás!A:F,6,0)="Igen","Igen","") | AD8: =IF(VLOOKUP(A8,Beosztás!A:G,7,0)="igen","igen","")
A9: ='Budapesti csoport'!A11 -> Horváth Tibor | B9: ='Budapesti csoport'!B11 -> SZÜTS KATALIN | C9: ='Budapesti csoport'!C11 -> M3 | D9: ='Budapesti csoport'!D11 -> Budapesti | E9: ='Budapesti csoport'!E11 -> aktív | F9: =[1]mátrix!E56 -> H1 | K9: =[1]mátrix!J56 -> 1 | O9: =[1]mátrix!N56 -> H1 | Q9: =[1]mátrix!P56 -> H1 | AC9: =IF(VLOOKUP(A9,Beosztás!A:F,6,0)="Igen","Igen","") | AD9: =IF(VLOOKUP(A9,Beosztás!A:G,7,0)="igen","igen","")
A10: ='Budapesti csoport'!A12 -> Lukács Anna | B10: ='Budapesti csoport'!B12 -> SZÜTS KATALIN | C10: ='Budapesti csoport'!C12 -> M3 | D10: ='Budapesti csoport'!D12 -> Budapesti | E10: ='Budapesti csoport'!E12 -> aktív | J10: =[1]mátrix!I57 -> KV | K10: =[1]mátrix!J57 -> 1 | O10: =[1]mátrix!N57 -> H1 | Q10: =[1]mátrix!P57 -> H1 | W10: H1 | AC10: =IF(VLOOKUP(A10,Beosztás!A:F,6,0)="Igen","Igen","") -> Igen | AD10: =IF(VLOOKUP(A10,Beosztás!A:G,7,0)="igen","igen","")
A11: ='Budapesti csoport'!A13 -> Gregor Katalin | B11: ='Budapesti csoport'!B13 -> SZÜTS KATALIN | C11: ='Budapesti csoport'!C13 -> Dél-Pest | D11: ='Budapesti csoport'!D13 -> Budapesti | E11: ='Budapesti csoport'!E13 -> aktív | K11: =[1]mátrix!J58 -> 1 | O11: =[1]mátrix!N58 -> H1 | Q11: =[1]mátrix!P58 -> H1 | AC11: =IF(VLOOKUP(A11,Beosztás!A:F,6,0)="Igen","Igen","") | AD11: =IF(VLOOKUP(A11,Beosztás!A:G,7,0)="igen","igen","")
A12: ='Budapesti csoport'!A14 -> Mitjans Mónika | B12: ='Budapesti csoport'!B14 -> SZÜTS KATALIN | C12: ='Budapesti csoport'!C14 -> Dél-Pest | D12: ='Budapesti csoport'!D14 -> Budapesti | E12: ='Budapesti csoport'!E14 -> aktív | K12: =[1]mátrix!J59 -> 1 | O12: =[1]mátrix!N59 -> H1 | Q12: =[1]mátrix!P59 -> H1 | R12: =[1]mátrix!Q59 -> H2 | Z12: =[1]mátrix!Y59 -> H1 | AC12: =IF(VLOOKUP(A12,Beosztás!A:F,6,0)="Igen","Igen","") -> Igen | AD12: =IF(VLOOKUP(A12,Beosztás!A:G,7,0)="igen","igen","")
A13: ='Budapesti csoport'!A15 -> Szijártó Szintia | B13: ='Budapesti csoport'!B15 -> SZÜTS KATALIN | C13: ='Budapesti csoport'!C15 -> Dél-Pest | D13: ='Budapesti csoport'!D15 -> Budapesti | E13: ='Budapesti csoport'!E15 -> aktív | K13: =[1]mátrix!J60 -> 1 | O13: =[1]mátrix!N60 -> H1 | Q13: =[1]mátrix!P60 -> H1 | AC13: =IF(VLOOKUP(A13,Beosztás!A:F,6,0)="Igen","Igen","") | AD13: =IF(VLOOKUP(A13,Beosztás!A:G,7,0)="igen","igen","")
A14: ='Budapesti csoport'!A16 -> Ferenczik Szilvia | B14: ='Budapesti csoport'!B16 -> SZÜTS KATALIN | C14: ='Budapesti csoport'!C16 -> Újbuda | D14: ='Budapesti csoport'!D16 -> Budapesti | E14: ='Budapesti csoport'!E16 -> aktív | K14: =[1]mátrix!J61 -> 1 | O14: =[1]mátrix!N61 -> H1 | Q14: =[1]mátrix!P61 -> H1 | AA14: =[1]mátrix!Z61 -> H1 | AC14: =IF(VLOOKUP(A14,Beosztás!A:F,6,0)="Igen","Igen","") | AD14: =IF(VLOOKUP(A14,Beosztás!A:G,7,0)="igen","igen","")
A15: ='Budapesti csoport'!A17 -> Németh-Szeghő Melinda | B15: ='Budapesti csoport'!B17 -> SZÜTS KATALIN | C15: ='Budapesti csoport'!C17 -> Újbuda | D15: ='Budapesti csoport'!D17 -> Budapesti | E15: ='Budapesti csoport'!E17 -> aktív | K15: =[1]mátrix!J62 -> 1 | O15: =[1]mátrix!N62 -> H1 | Q15: =[1]mátrix!P62 -> H1 | R15: =[1]mátrix!Q62 -> H2 | Z15: =[1]mátrix!Y62 -> H1 | AA15: =[1]mátrix!Z62 -> H1 | AC15: =IF(VLOOKUP(A15,Beosztás!A:F,6,0)="Igen","Igen","") | AD15: =IF(VLOOKUP(A15,Beosztás!A:G,7,0)="igen","igen","")
A16: ='Budapesti csoport'!A18 -> Polányi Viktória | B16: ='Budapesti csoport'!B18 -> SZÜTS KATALIN | C16: ='Budapesti csoport'!C18 -> Újbuda | D16: ='Budapesti csoport'!D18 -> Budapesti | E16: ='Budapesti csoport'!E18 -> aktív | K16: =[1]mátrix!J63 -> 1 | O16: =[1]mátrix!N63 -> H1 | Q16: =[1]mátrix!P63 -> H1 | AA16: =[1]mátrix!Z63 -> H1 | AC16: =IF(VLOOKUP(A16,Beosztás!A:F,6,0)="Igen","Igen","") | AD16: =IF(VLOOKUP(A16,Beosztás!A:G,7,0)="igen","igen","")
A17: ='Budapesti csoport'!A19 -> Szabó Zsuzsanna | B17: ='Budapesti csoport'!B19 -> SZÜTS KATALIN | C17: ='Budapesti csoport'!C19 -> Újbuda | D17: ='Budapesti csoport'!D19 -> Budapesti | E17: ='Budapesti csoport'!E19 -> aktív | K17: =[1]mátrix!J64 -> 1 | O17: =[1]mátrix!N64 -> H1 | Q17: =[1]mátrix!P64 -> H1 | AA17: =[1]mátrix!Z64 -> H1 | AC17: =IF(VLOOKUP(A17,Beosztás!A:F,6,0)="Igen","Igen","") | AD17: =IF(VLOOKUP(A17,Beosztás!A:G,7,0)="igen","igen","")
A18: ='Budapesti csoport'!A20 -> 0 | B18: ='Budapesti csoport'!B20 -> 0 | C18: ='Budapesti csoport'!C20 -> 0 | D18: ='Budapesti csoport'!D20 -> 0 | E18: ='Budapesti csoport'!E20 -> 0 | AC18: =IF(VLOOKUP(A18,Beosztás!A:F,6,0)="Igen","Igen","") | AD18: =IF(VLOOKUP(A18,Beosztás!A:G,7,0)="igen","igen","")
A19: ='Budapesti csoport'!A21 -> 0 | B19: ='Budapesti csoport'!B21 -> 0 | C19: ='Budapesti csoport'!C21 -> 0 | D19: ='Budapesti csoport'!D21 -> 0 | E19: ='Budapesti csoport'!E21 -> 0 | AC19: =IF(VLOOKUP(A19,Beosztás!A:F,6,0)="Igen","Igen","") | AD19: =IF(VLOOKUP(A19,Beosztás!A:G,7,0)="igen","igen","")
A20: ='Budapesti csoport'!A22 -> 0 | B20: ='Budapesti csoport'!B22 -> 0 | C20: ='Budapesti csoport'!C22 -> 0 | D20: ='Budapesti csoport'!D22 -> 0 | E20: ='Budapesti csoport'!E22 -> 0 | AC20: =IF(VLOOKUP(A20,Beosztás!A:F,6,0)="Igen","Igen","") | AD20: =IF(VLOOKUP(A20,Beosztás!A:G,7,0)="igen","igen","")
A21: ='Budapesti csoport'!A23 -> 0 | B21: ='Budapesti csoport'!B23 -> 0 | C21: ='Budapesti csoport'!C23 -> 0 | D21: ='Budapesti csoport'!D23 -> 0 | E21: ='Budapesti csoport'!E23 -> 0 | AC21: =IF(VLOOKUP(A21,Beosztás!A:F,6,0)="Igen","Igen","") | AD21: =IF(VLOOKUP(A21,Beosztás!A:G,7,0)="igen","igen","")
A22: ='Budapesti csoport'!A24 -> 0 | B22: ='Budapesti csoport'!B24 -> 0 | C22: ='Budapesti csoport'!C24 -> 0 | D22: ='Budapesti csoport'!D24 -> 0 | E22: ='Budapesti csoport'!E24 -> 0 | AC22: =IF(VLOOKUP(A22,Beosztás!A:F,6,0)="Igen","Igen","") | AD22: =IF(VLOOKUP(A22,Beosztás!A:G,7,0)="igen","igen","")
A23: ='Budapesti csoport'!A25 -> 0 | B23: ='Budapesti csoport'!B25 -> 0 | C23: ='Budapesti csoport'!C25 -> 0 | D23: ='Budapesti csoport'!D25 -> 0 | E23: ='Budapesti csoport'!E25 -> 0 | AC23: =IF(VLOOKUP(A23,Beosztás!A:F,6,0)="Igen","Igen","") | AD23: =IF(VLOOKUP(A23,Beosztás!A:G,7,0)="igen","igen","")
A24: ='Budapesti csoport'!A26 -> 0 | B24: ='Budapesti csoport'!B26 -> 0 | C24: ='Budapesti csoport'!C26 -> 0 | D24: ='Budapesti csoport'!D26 -> 0 | E24: ='Budapesti csoport'!E26 -> 0 | AC24: =IF(VLOOKUP(A24,Beosztás!A:F,6,0)="Igen","Igen","") | AD24: =IF(VLOOKUP(A24,Beosztás!A:G,7,0)="igen","igen","")
A25: ='Budapesti csoport'!A27 -> 0 | B25: ='Budapesti csoport'!B27 -> 0 | C25: ='Budapesti csoport'!C27 -> 0 | D25: ='Budapesti csoport'!D27 -> 0 | E25: ='Budapesti csoport'!E27 -> 0 | AC25: =IF(VLOOKUP(A25,Beosztás!A:F,6,0)="Igen","Igen","") | AD25: =IF(VLOOKUP(A25,Beosztás!A:G,7,0)="igen","igen","")
A26: ='Budapesti csoport'!A28 -> 0 | B26: ='Budapesti csoport'!B28 -> 0 | C26: ='Budapesti csoport'!C28 -> 0 | D26: ='Budapesti csoport'!D28 -> 0 | E26: ='Budapesti csoport'!E28 -> 0 | AC26: =IF(VLOOKUP(A26,Beosztás!A:F,6,0)="Igen","Igen","") | AD26: =IF(VLOOKUP(A26,Beosztás!A:G,7,0)="igen","igen","")
A27: ='Budapesti csoport'!A29 -> 0 | B27: ='Budapesti csoport'!B29 -> 0 | C27: ='Budapesti csoport'!C29 -> 0 | D27: ='Budapesti csoport'!D29 -> 0 | E27: ='Budapesti csoport'!E29 -> 0 | AC27: =IF(VLOOKUP(A27,Beosztás!A:F,6,0)="Igen","Igen","") | AD27: =IF(VLOOKUP(A27,Beosztás!A:G,7,0)="igen","igen","")
A28: ='Budapesti csoport'!A30 -> 0 | B28: ='Budapesti csoport'!B30 -> 0 | C28: ='Budapesti csoport'!C30 -> 0 | D28: ='Budapesti csoport'!D30 -> 0 | E28: ='Budapesti csoport'!E30 -> 0 | AC28: =IF(VLOOKUP(A28,Beosztás!A:F,6,0)="Igen","Igen","") | AD28: =IF(VLOOKUP(A28,Beosztás!A:G,7,0)="igen","igen","")
A29: ='Budapesti csoport'!A31 -> 0 | B29: ='Budapesti csoport'!B31 -> 0 | C29: ='Budapesti csoport'!C31 -> 0 | D29: ='Budapesti csoport'!D31 -> 0 | E29: ='Budapesti csoport'!E31 -> 0 | AC29: =IF(VLOOKUP(A29,Beosztás!A:F,6,0)="Igen","Igen","") | AD29: =IF(VLOOKUP(A29,Beosztás!A:G,7,0)="igen","igen","")
... A60: ='Budapesti csoport'!A62 -> 0 | B60: ='Budapesti csoport'!B62 -> 0 | C60: ='Budapesti csoport'!C62 -> 0 | D60: ='Budapesti csoport'!D62 -> 0 | E60: ='Budapesti csoport'!E62 -> 0 | AC60: =IF(VLOOKUP(A60,Beosztás!A:F,6,0)="Igen","Igen","") | AD60: =IF(VLOOKUP(A60,Beosztás!A:G,7,0)="igen","igen","")
A61: ='Keleti csoport'!A15 -> Bércesi Richárd Tamásné | B61: ='Keleti csoport'!B15 -> SZABÓ ZSUZSANNA | C61: ='Keleti csoport'!C15 -> Miskolc | D61: ='Keleti csoport'!D15 -> Keleti | E61: ='Keleti csoport'!E15 -> aktív | F61: H1 | K61: =[1]mátrix!J27 -> 1 | M61: H1 | O61: =[1]mátrix!N27 -> H1 | Q61: H1 | X61: 3 | AD61: =IF(VLOOKUP(A61,Beosztás!A:G,7,0)="igen","igen","")
A62: ='Keleti csoport'!A5 -> Boros Viktor | B62: ='Keleti csoport'!B5 -> SZABÓ ZSUZSANNA | C62: ='Keleti csoport'!C5 -> Szeged | D62: ='Keleti csoport'!D5 -> Keleti | E62: ='Keleti csoport'!E5 -> aktív | K62: =[1]mátrix!J28 -> 1 | L62: =[1]mátrix!K28 -> H1 | O62: =[1]mátrix!N28 -> H1 | Q62: =[1]mátrix!P28 -> H1 | W62: H1 | AC62: igen | AD62: =IF(VLOOKUP(A62,Beosztás!A:G,7,0)="igen","igen","")
A63: ='Keleti csoport'!A6 -> Kecskés Erzsébet | B63: ='Keleti csoport'!B6 -> SZABÓ ZSUZSANNA | C63: ='Keleti csoport'!C6 -> Szeged | D63: ='Keleti csoport'!D6 -> Keleti | E63: ='Keleti csoport'!E6 -> aktív | F63: =[1]mátrix!E29 -> H1 | J63: 3 | K63: =[1]mátrix!J29 -> 1 | L63: H1 | M63: H1 | O63: =[1]mátrix!N29 -> H1 | Q63: =[1]mátrix!P29 -> H1 | R63: 3 | AD63: =IF(VLOOKUP(A63,Beosztás!A:G,7,0)="igen","igen","")
A64: ='Keleti csoport'!A7 -> Oláh Imola | B64: ='Keleti csoport'!B7 -> SZABÓ ZSUZSANNA | C64: ='Keleti csoport'!C7 -> Szeged | D64: ='Keleti csoport'!D7 -> Keleti | E64: ='Keleti csoport'!E7 -> aktív | F64: =[1]mátrix!E30 -> H1 | G64: H1 | K64: =[1]mátrix!J30 -> 1 | L64: BF | O64: H1 | Q64: H1 | W64: H1 | AC64: igen | AD64: =IF(VLOOKUP(A64,Beosztás!A:G,7,0)="igen","igen","")
A65: ='Keleti csoport'!A8 -> Fitos-Gyurcsó Eszter | B65: ='Keleti csoport'!B8 -> SZABÓ ZSUZSANNA | C65: ='Keleti csoport'!C8 -> Szolnok | D65: ='Keleti csoport'!D8 -> Keleti | E65: ='Keleti csoport'!E8 -> aktív | F65: =[1]mátrix!E31 -> H1 | K65: =[1]mátrix!J31 -> 1 | L65: =[1]mátrix!K31 -> H1 | O65: =[1]mátrix!N31 -> H1 | Q65: 3 | T65: H1 | AC65: =IF(VLOOKUP(A65,Beosztás!A:F,6,0)="Igen","Igen","") | AD65: =IF(VLOOKUP(A65,Beosztás!A:G,7,0)="igen","igen","")
A66: ='Keleti csoport'!A9 -> Láposi Dóra | B66: ='Keleti csoport'!B9 -> SZABÓ ZSUZSANNA | C66: ='Keleti csoport'!C9 -> Szolnok | D66: ='Keleti csoport'!D9 -> Keleti | E66: ='Keleti csoport'!E9 -> aktív | F66: =[1]mátrix!E32 -> H1 | K66: =[1]mátrix!J32 -> 1 | L66: =[1]mátrix!K32 -> H1 | M66: H1 | O66: =[1]mátrix!N32 -> H1 | Q66: =[1]mátrix!P32 -> H1 | AC66: =IF(VLOOKUP(A66,Beosztás!A:F,6,0)="Igen","Igen","") | AD66: =IF(VLOOKUP(A66,Beosztás!A:G,7,0)="igen","igen","")
A67: ='Keleti csoport'!A10 -> Polgár Rubina | B67: ='Keleti csoport'!B10 -> SZABÓ ZSUZSANNA | C67: ='Keleti csoport'!C10 -> Szolnok | D67: ='Keleti csoport'!D10 -> Keleti | E67: ='Keleti csoport'!E10 -> aktív | F67: =[1]mátrix!E33 -> H1 | K67: =[1]mátrix!J33 -> 1 | L67: H1 | O67: =[1]mátrix!N33 -> H1 | Q67: =[1]mátrix!P33 -> H1 | AC67: =IF(VLOOKUP(A67,Beosztás!A:F,6,0)="Igen","Igen","") | AD67: =IF(VLOOKUP(A67,Beosztás!A:G,7,0)="igen","igen","")
A68: ='Keleti csoport'!A11 -> Bodnárné Pádár Judit | B68: ='Keleti csoport'!B11 -> SZABÓ ZSUZSANNA | C68: ='Keleti csoport'!C11 -> Debrecen | D68: ='Keleti csoport'!D11 -> Keleti | E68: ='Keleti csoport'!E11 -> aktív | F68: H1 | K68: =[1]mátrix!J34 -> 1 | O68: =[1]mátrix!N34 -> H1 | Q68: =[1]mátrix!P34 -> H1 | AD68: =IF(VLOOKUP(A68,Beosztás!A:G,7,0)="igen","igen","")
A69: ='Keleti csoport'!A12 -> Emődi Anett | B69: ='Keleti csoport'!B12 -> SZABÓ ZSUZSANNA | C69: ='Keleti csoport'!C12 -> Debrecen | D69: ='Keleti csoport'!D12 -> Keleti | E69: ='Keleti csoport'!E12 -> inaktív | K69: =[1]mátrix!J35 -> 1 | O69: =[1]mátrix!N35 -> H1 | P69: =[1]mátrix!O35 -> H2 | Q69: =[1]mátrix!P35 -> H1 | AC69: =IF(VLOOKUP(A69,Beosztás!A:F,6,0)="Igen","Igen","") | AD69: =IF(VLOOKUP(A69,Beosztás!A:G,7,0)="igen","igen","")
A70: ='Keleti csoport'!A13 -> Gaja Dorottya | B70: ='Keleti csoport'!B13 -> SZABÓ ZSUZSANNA | C70: ='Keleti csoport'!C13 -> Debrecen | D70: ='Keleti csoport'!D13 -> Keleti | E70: ='Keleti csoport'!E13 -> aktív | K70: =[1]mátrix!J36 -> 1 | O70: =[1]mátrix!N36 -> H1 | Q70: BF | AC70: =IF(VLOOKUP(A70,Beosztás!A:F,6,0)="Igen","Igen","") | AD70: =IF(VLOOKUP(A70,Beosztás!A:G,7,0)="igen","igen","")
...

Sheet ÜGYFÉLLEVELEZÉS.csop.
R1: =Beosztás!T1 -> 2026.03.01 | S1: =R1+1 -> 46083 | T1: =S1+1 -> 46084 | U1: =T1+1 -> 46085 | V1: =U1+1 -> 46086 | W1: =V1+1 -> 46087 | X1: =W1+1 -> 46088 | Y1: =X1+1 -> 46089 | Z1: =Y1+1 -> 46090 | ... AV1: =AU1+1 -> 46112 | AW1: Összes munkanap szabadsággal | AX1: Összegző
R2: =WEEKDAY(R1) -> 1 | S2: =WEEKDAY(S1) -> 2 | T2: =WEEKDAY(T1) -> 3 | U2: =WEEKDAY(U1) -> 4 | V2: =WEEKDAY(V1) -> 5 | W2: =WEEKDAY(W1) -> 6 | X2: =WEEKDAY(X1) -> 7 | Y2: =WEEKDAY(Y1) -> 1 | ... AV2: =WEEKDAY(AV1) -> 3
F3: Angol nyelv | G3: Német nyelv | H3: Személyes Üszi | I3: HD Levél | J3: UD levél | K3: Angol levél | L3: Jogsegély | M3: CC | N3: Video | O3: Belfölfi ügykezelés | P3: Külföldi ügykezelés | Q3: E-csoportos | R3: =IF(R2=1,"Vasárnap",IF(R2=2,"Hétfő",IF(R2=3,"Kedd",IF(R2=4,"Szerda",IF(R2=5,"Csütörtök",IF(R2=6,"Péntek",IF(R2=7,"Szombat",""))))))) -> Vasárnap | S3: =IF(S2=1,"Vasárnap",IF(S2=2,"Hétfő",IF(S2=3,"Kedd",IF(S2=4,"Szerda",IF(S2=5,"Csütörtök",IF(S2=6,"Péntek",IF(S2=7,"Szombat",""))))))) -> Hétfő | T3: =IF(T2=1,"Vasárnap",IF(T2=2,"Hétfő",IF(T2=3,"Kedd",IF(T2=4,"Szerda",IF(T2=5,"Csütörtök",IF(T2=6,"Péntek",IF(T2=7,"Szombat",""))))))) -> Kedd | U3: =IF(U2=1,"Vasárnap",IF(U2=2,"Hétfő",IF(U2=3,"Kedd",IF(U2=4,"Szerda",IF(U2=5,"Csütörtök",IF(U2=6,"Péntek",IF(U2=7,"Szombat",""))))))) -> Szerda | V3: =IF(V2=1,"Vasárnap",IF(V2=2,"Hétfő",IF(V2=3,"Kedd",IF(V2=4,"Szerda",IF(V2=5,"Csütörtök",IF(V2=6,"Péntek",IF(V2=7,"Szombat",""))))))) -> Csütörtök | W3: =IF(W2=1,"Vasárnap",IF(W2=2,"Hétfő",IF(W2=3,"Kedd",IF(W2=4,"Szerda",IF(W2=5,"Csütörtök",IF(W2=6,"Péntek",IF(W2=7,"Szombat",""))))))) -> Péntek | X3: =IF(X2=1,"Vasárnap",IF(X2=2,"Hétfő",IF(X2=3,"Kedd",IF(X2=4,"Szerda",IF(X2=5,"Csütörtök",IF(X2=6,"Péntek",IF(X2=7,"Szombat",""))))))) -> Szombat | Y3: =IF(Y2=1,"Vasárnap",IF(Y2=2,"Hétfő",IF(Y2=3,"Kedd",IF(Y2=4,"Szerda",IF(Y2=5,"Csütörtök",IF(Y2=6,"Péntek",IF(Y2=7,"Szombat",""))))))) -> Vasárnap | ... AV3: =IF(AV2=1,"Vasárnap",IF(AV2=2,"Hétfő",IF(AV2=3,"Kedd",IF(AV2=4,"Szerda",IF(AV2=5,"Csütörtök",IF(AV2=6,"Péntek",IF(AV2=7,"Szombat",""))))))) -> Kedd | AX3: Angol levelezés | AY3: angol SOS | AZ3: Betanítás | BA3: Betanulás | BB3: CC | BC3: CC angol | BD3: CC német | BE3: CC NM | BF3: e-csoportos | BG3: Egyéb ügyintézés | BH3: KPLLC ügyintézés | BI3: E-ÜSZI | BJ3: HUGO | BK3: HUGO (@) | BL3: Iktatás | BM3: Jelölő (@) | BN3: Jogsegély levelezés | BO3: Jogsegély szignálás | BP3: Külföldi irodák | BQ3: Levélírás | BR3: Panaszkezelés | BS3: Postakönyv | BT3: Tesztelés | BU3: ÜSZI | BV3: Video | BW3: Oktatás - külső | BX3: P | BY3: B | BZ3: SZ | CA3: Video 8-16 | CB3: Video 9-17 | CC3: Video 10-18
A4: Név | B4: Csoport vezető | C4: Terület | D4: Csoport | E4: státusz | CA4: =COUNTIF($R4:$AV4,CA$3) -> 0 | CB4: =COUNTIF($R4:$AV4,CB$3) -> 0 | CC4: =COUNTIF($R4:$AV4,CC$3) -> 0
A5: =admin_Levelezés!A2 -> Ádám Zoltán | B5: =admin_Levelezés!B2 -> SZABÓ ÁGNES | C5: =admin_Levelezés!C2 -> Gyöngyös | D5: =admin_Levelezés!D2 -> ÜGYFÉLLEVELEZÉS | E5: =admin_Levelezés!E2 -> aktív | F5: =admin_Levelezés!F2 -> nem | G5: =admin_Levelezés!G2 -> 0 | H5: =admin_Levelezés!H2 -> nem | ... Q5: =admin_Levelezés!Q2 -> 0 | S5: HUGO (@) | T5: HUGO (@) | U5: HUGO | V5: HUGO | W5: HUGO | Z5: HUGO (@) | AA5: HUGO (@) | AB5: HUGO | AC5: HUGO | AD5: HUGO | AG5: HUGO (@) | AH5: HUGO (@) | AI5: HUGO | AJ5: HUGO | AK5: HUGO | AN5: HUGO (@) | AO5: HUGO (@) | AP5: HUGO | AQ5: HUGO | AR5: HUGO | AU5: HUGO (@) | AV5: HUGO (@) | AW5: =SUM(AX5:BW5)+BZ5 -> 22 | AX5: =COUNTIF($R5:$AV5,AX$3) -> 0 | AY5: =COUNTIF($R5:$AV5,AY$3) -> 0 | AZ5: =COUNTIF($R5:$AV5,AZ$3) -> 0 | BA5: =COUNTIF($R5:$AV5,BA$3) -> 0 | BB5: =COUNTIF($R5:$AV5,BB$3) -> 0 | BC5: =COUNTIF($R5:$AV5,BC$3) -> 0 | BD5: =COUNTIF($R5:$AV5,BD$3) -> 0 | BE5: =COUNTIF($R5:$AV5,BE$3) -> 0 | ... BP5: =COUNTIF($R5:$AV5,BP$3) -> 0 | BQ5: =COUNTIF($R5:$AV5,BQ$3)+COUNTIF($R5:$AV5,"levelezés em") -> 0 | BR5: =COUNTIF($R5:$AV5,BR$3) -> 0 | BS5: =COUNTIF($R5:$AV5,BS$3) -> 0 | BT5: =COUNTIF($R5:$AV5,BT$3) -> 0 | BU5: =COUNTIF($R5:$AV5,BU$3) -> 0 | BV5: =SUM(CA5:CC5) -> 0 | BW5: =COUNTIF($R5:$AV5,BW$3) -> 0 | BX5: =COUNTIF($R5:$AV5,BX$3) -> 0 | BY5: =COUNTIF($R5:$AV5,BY$3) -> 0 | BZ5: =COUNTIF($R5:$AV5,BZ$3) -> 0 | CA5: =COUNTIF($R5:$AV5,CA$3) -> 0 | CB5: =COUNTIF($R5:$AV5,CB$3) -> 0 | CC5: =COUNTIF($R5:$AV5,CC$3) -> 0
A6: =admin_Levelezés!A3 -> Bolyhosné Kovács Judit | B6: =admin_Levelezés!B3 -> SZABÓ ÁGNES | C6: =admin_Levelezés!C3 -> Gyöngyös | D6: =admin_Levelezés!D3 -> ÜGYFÉLLEVELEZÉS | E6: =admin_Levelezés!E3 -> aktív | F6: nem | G6: 0 | H6: nem | I6: igen | J6: nem | K6: nem | L6: nem | M6: nem | N6: nem | O6: nem | P6: igen | Q6: 0 | S6: Levélírás | T6: Levélírás | U6: Levélírás | V6: Levélírás | W6: SZ | Z6: Levélírás | AA6: Levélírás | AB6: Levélírás | AC6: Levélírás | AD6: Levélírás | AG6: Levélírás | AH6: Levélírás | AI6: Levélírás | AJ6: Levélírás | AK6: Levélírás | AN6: SZ | AO6: SZ | AP6: SZ | AQ6: SZ | AR6: SZ | AU6: Levélírás | AV6: Levélírás | AW6: =SUM(AX6:BW6)+BZ6 -> 22 | AX6: =COUNTIF($R6:$AV6,AX$3) -> 0 | AY6: =COUNTIF($R6:$AV6,AY$3) -> 0 | AZ6: =COUNTIF($R6:$AV6,AZ$3) -> 0 | BA6: =COUNTIF($R6:$AV6,BA$3) -> 0 | BB6: =COUNTIF($R6:$AV6,BB$3) -> 0 | BC6: =COUNTIF($R6:$AV6,BC$3) -> 0 | BD6: =COUNTIF($R6:$AV6,BD$3) -> 0 | BE6: =COUNTIF($R6:$AV6,BE$3) -> 0 | ... BP6: =COUNTIF($R6:$AV6,BP$3) -> 0 | BQ6: =COUNTIF($R6:$AV6,BQ$3)+COUNTIF($R6:$AV6,"levelezés em") -> 16 | BR6: =COUNTIF($R6:$AV6,BR$3) -> 0 | BS6: =COUNTIF($R6:$AV6,BS$3) -> 0 | BT6: =COUNTIF($R6:$AV6,BT$3) -> 0 | BU6: =COUNTIF($R6:$AV6,BU$3) -> 0 | BV6: =SUM(CA6:CC6) -> 0 | BW6: =COUNTIF($R6:$AV6,BW$3) -> 0 | BX6: =COUNTIF($R6:$AV6,BX$3) -> 0 | BY6: =COUNTIF($R6:$AV6,BY$3) -> 0 | BZ6: =COUNTIF($R6:$AV6,BZ$3) -> 6 | CA6: =COUNTIF($R6:$AV6,CA$3) -> 0 | CB6: =COUNTIF($R6:$AV6,CB$3) -> 0 | CC6: =COUNTIF($R6:$AV6,CC$3) -> 0
A7: =admin_Levelezés!A4 -> Bornemissza Noémi | B7: =admin_Levelezés!B4 -> SZABÓ ÁGNES | C7: =admin_Levelezés!C4 -> Gyöngyös | D7: =admin_Levelezés!D4 -> ÜGYFÉLLEVELEZÉS | E7: =admin_Levelezés!E4 -> aktív | F7: nem | G7: 0 | H7: nem | I7: igen | J7: igen | K7: nem | L7: igen | M7: nem | N7: nem | O7: nem | P7: igen | Q7: 0 | S7: Külföldi irodák | T7: Külföldi irodák | U7: Külföldi irodák | V7: Külföldi irodák | W7: Külföldi irodák | Z7: Külföldi irodák | AA7: Külföldi irodák | AB7: Külföldi irodák | AC7: Külföldi irodák | AD7: SZ | AG7: Külföldi irodák | AH7: Külföldi irodák | AI7: Külföldi irodák | AJ7: Külföldi irodák | AK7: Külföldi irodák | AN7: Külföldi irodák | AO7: Külföldi irodák | AP7: Külföldi irodák | AQ7: Külföldi irodák | AR7: SZ | AU7: Külföldi irodák | AV7: Külföldi irodák | AW7: =SUM(AX7:BW7)+BZ7 -> 22 | AX7: =COUNTIF($R7:$AV7,AX$3) -> 0 | AY7: =COUNTIF($R7:$AV7,AY$3) -> 0 | AZ7: =COUNTIF($R7:$AV7,AZ$3) -> 0 | BA7: =COUNTIF($R7:$AV7,BA$3) -> 0 | BB7: =COUNTIF($R7:$AV7,BB$3) -> 0 | BC7: =COUNTIF($R7:$AV7,BC$3) -> 0 | BD7: =COUNTIF($R7:$AV7,BD$3) -> 0 | BE7: =COUNTIF($R7:$AV7,BE$3) -> 0 | ... BP7: =COUNTIF($R7:$AV7,BP$3) -> 20 | BQ7: =COUNTIF($R7:$AV7,BQ$3)+COUNTIF($R7:$AV7,"levelezés em") -> 0 | BR7: =COUNTIF($R7:$AV7,BR$3) -> 0 | BS7: =COUNTIF($R7:$AV7,BS$3) -> 0 | BT7: =COUNTIF($R7:$AV7,BT$3) -> 0 | BU7: =COUNTIF($R7:$AV7,BU$3) -> 0 | BV7: =SUM(CA7:CC7) -> 0 | BW7: =COUNTIF($R7:$AV7,BW$3) -> 0 | BX7: =COUNTIF($R7:$AV7,BX$3) -> 0 | BY7: =COUNTIF($R7:$AV7,BY$3) -> 0 | BZ7: =COUNTIF($R7:$AV7,BZ$3) -> 2 | CA7: =COUNTIF($R7:$AV7,CA$3) -> 0 | CB7: =COUNTIF($R7:$AV7,CB$3) -> 0 | CC7: =COUNTIF($R7:$AV7,CC$3) -> 0
A8: =admin_Levelezés!A5 -> Erberling Zsófia | B8: =admin_Levelezés!B5 -> SZABÓ ÁGNES | C8: =admin_Levelezés!C5 -> Gyöngyös | D8: =admin_Levelezés!D5 -> ÜGYFÉLLEVELEZÉS | E8: =admin_Levelezés!E5 -> aktív | F8: nem | G8: 0 | H8: nem | I8: nem | J8: igen | K8: igen | L8: igen | M8: nem | N8: nem | O8: nem | P8: nem | Q8: 0 | S8: Jogsegély szignálás | T8: Jogsegély szignálás | U8: Jogsegély levelezés | V8: Jogsegély levelezés | W8: Jogsegély levelezés | Z8: Jogsegély szignálás | AA8: Jogsegély szignálás | AB8: Jogsegély levelezés | AC8: Jogsegély levelezés | AD8: Jogsegély levelezés | AG8: Jogsegély szignálás | AH8: Jogsegély szignálás | AI8: Jogsegély levelezés | AJ8: Jogsegély levelezés | AK8: Jogsegély levelezés | AN8: Jogsegély szignálás | AO8: Jogsegély szignálás | AP8: Jogsegély levelezés | AQ8: Jogsegély levelezés | AR8: Jogsegély levelezés | AU8: Jogsegély szignálás | AV8: Jogsegély szignálás | AW8: =SUM(AX8:BW8)+BZ8 -> 22 | AX8: =COUNTIF($R8:$AV8,AX$3) -> 0 | AY8: =COUNTIF($R8:$AV8,AY$3) -> 0 | AZ8: =COUNTIF($R8:$AV8,AZ$3) -> 0 | BA8: =COUNTIF($R8:$AV8,BA$3) -> 0 | BB8: =COUNTIF($R8:$AV8,BB$3) -> 0 | BC8: =COUNTIF($R8:$AV8,BC$3) -> 0 | BD8: =COUNTIF($R8:$AV8,BD$3) -> 0 | BE8: =COUNTIF($R8:$AV8,BE$3) -> 0 | ... BP8: =COUNTIF($R8:$AV8,BP$3) -> 0 | BQ8: =COUNTIF($R8:$AV8,BQ$3)+COUNTIF($R8:$AV8,"levelezés em") -> 0 | BR8: =COUNTIF($R8:$AV8,BR$3) -> 0 | BS8: =COUNTIF($R8:$AV8,BS$3) -> 0 | BT8: =COUNTIF($R8:$AV8,BT$3) -> 0 | BU8: =COUNTIF($R8:$AV8,BU$3) -> 0 | BV8: =SUM(CA8:CC8) -> 0 | BW8: =COUNTIF($R8:$AV8,BW$3) -> 0 | BX8: =COUNTIF($R8:$AV8,BX$3) -> 0 | BY8: =COUNTIF($R8:$AV8,BY$3) -> 0 | BZ8: =COUNTIF($R8:$AV8,BZ$3) -> 0 | CA8: =COUNTIF($R8:$AV8,CA$3) -> 0 | CB8: =COUNTIF($R8:$AV8,CB$3) -> 0 | CC8: =COUNTIF($R8:$AV8,CC$3) -> 0
A9: =admin_Levelezés!A6 -> Forgó Adrienn | B9: =admin_Levelezés!B6 -> SZABÓ ÁGNES | C9: =admin_Levelezés!C6 -> Gyöngyös | D9: =admin_Levelezés!D6 -> ÜGYFÉLLEVELEZÉS | E9: =admin_Levelezés!E6 -> aktív | F9: nem | G9: 0 | H9: nem | I9: nem | J9: igen | K9: igen | L9: igen | M9: nem | N9: nem | O9: nem | P9: nem | Q9: 0 | S9: HUGO | T9: HUGO | U9: HUGO (@) | V9: HUGO | W9: HUGO | Z9: HUGO | AA9: HUGO | AB9: HUGO (@) | AC9: HUGO | AD9: HUGO | AG9: HUGO | AH9: HUGO | AI9: HUGO (@) | AJ9: SZ | AK9: SZ | AN9: HUGO | AO9: HUGO | AP9: HUGO (@) | AQ9: HUGO | AR9: HUGO | AU9: HUGO | AV9: HUGO | AW9: =SUM(AX9:BW9)+BZ9 -> 22 | AX9: =COUNTIF($R9:$AV9,AX$3) -> 0 | AY9: =COUNTIF($R9:$AV9,AY$3) -> 0 | AZ9: =COUNTIF($R9:$AV9,AZ$3) -> 0 | BA9: =COUNTIF($R9:$AV9,BA$3) -> 0 | BB9: =COUNTIF($R9:$AV9,BB$3) -> 0 | BC9: =COUNTIF($R9:$AV9,BC$3) -> 0 | BD9: =COUNTIF($R9:$AV9,BD$3) -> 0 | BE9: =COUNTIF($R9:$AV9,BE$3) -> 0 | ... BP9: =COUNTIF($R9:$AV9,BP$3) -> 0 | BQ9: =COUNTIF($R9:$AV9,BQ$3)+COUNTIF($R9:$AV9,"levelezés em") -> 0 | BR9: =COUNTIF($R9:$AV9,BR$3) -> 0 | BS9: =COUNTIF($R9:$AV9,BS$3) -> 0 | BT9: =COUNTIF($R9:$AV9,BT$3) -> 0 | BU9: =COUNTIF($R9:$AV9,BU$3) -> 0 | BV9: =SUM(CA9:CC9) -> 0 | BW9: =COUNTIF($R9:$AV9,BW$3) -> 0 | BX9: =COUNTIF($R9:$AV9,BX$3) -> 0 | BY9: =COUNTIF($R9:$AV9,BY$3) -> 0 | BZ9: =COUNTIF($R9:$AV9,BZ$3) -> 2 | CA9: =COUNTIF($R9:$AV9,CA$3) -> 0 | CB9: =COUNTIF($R9:$AV9,CB$3) -> 0 | CC9: =COUNTIF($R9:$AV9,CC$3) -> 0
A10: =admin_Levelezés!A7 -> György Sándorné | B10: =admin_Levelezés!B7 -> SZABÓ ÁGNES | C10: =admin_Levelezés!C7 -> Gyöngyös | D10: =admin_Levelezés!D7 -> ÜGYFÉLLEVELEZÉS | E10: =admin_Levelezés!E7 -> aktív | F10: nem | G10: 0 | H10: nem | I10: igen | J10: nem | K10: nem | L10: nem | M10: nem | N10: nem | O10: nem | P10: igen | Q10: 0 | S10: Levélírás | T10: Levélírás | U10: Levélírás | V10: Levélírás | W10: Levélírás | Z10: Levélírás | AA10: Levélírás | AB10: Levélírás | AC10: Levélírás | AD10: Levélírás | AG10: Levélírás | AH10: Levélírás | AI10: Levélírás | AJ10: Levélírás | AK10: Levélírás | AN10: Levélírás | AO10: Levélírás | AP10: Levélírás | AQ10: Levélírás | AR10: SZ | AU10: SZ | AV10: SZ | AW10: =SUM(AX10:BW10)+BZ10 -> 22 | AX10: =COUNTIF($R10:$AV10,AX$3) -> 0 | AY10: =COUNTIF($R10:$AV10,AY$3) -> 0 | AZ10: =COUNTIF($R10:$AV10,AZ$3) -> 0 | BA10: =COUNTIF($R10:$AV10,BA$3) -> 0 | BB10: =COUNTIF($R10:$AV10,BB$3) -> 0 | BC10: =COUNTIF($R10:$AV10,BC$3) -> 0 | BD10: =COUNTIF($R10:$AV10,BD$3) -> 0 | BE10: =COUNTIF($R10:$AV10,BE$3) -> 0 | ... BP10: =COUNTIF($R10:$AV10,BP$3) -> 0 | BQ10: =COUNTIF($R10:$AV10,BQ$3)+COUNTIF($R10:$AV10,"levelezés em") -> 19 | BR10: =COUNTIF($R10:$AV10,BR$3) -> 0 | BS10: =COUNTIF($R10:$AV10,BS$3) -> 0 | BT10: =COUNTIF($R10:$AV10,BT$3) -> 0 | BU10: =COUNTIF($R10:$AV10,BU$3) -> 0 | BV10: =SUM(CA10:CC10) -> 0 | BW10: =COUNTIF($R10:$AV10,BW$3) -> 0 | BX10: =COUNTIF($R10:$AV10,BX$3) -> 0 | BY10: =COUNTIF($R10:$AV10,BY$3) -> 0 | BZ10: =COUNTIF($R10:$AV10,BZ$3) -> 3 | CA10: =COUNTIF($R10:$AV10,CA$3) -> 0 | CB10: =COUNTIF($R10:$AV10,CB$3) -> 0 | CC10: =COUNTIF($R10:$AV10,CC$3) -> 0
A11: =admin_Levelezés!A8 -> Keresztes Ámon | B11: =admin_Levelezés!B8 -> SZABÓ ÁGNES | C11: =admin_Levelezés!C8 -> Gyöngyös | D11: =admin_Levelezés!D8 -> ÜGYFÉLLEVELEZÉS | E11: =admin_Levelezés!E8 -> aktív | F11: nem | G11: 0 | H11: nem | I11: igen | J11: nem | K11: nem | L11: nem | M11: nem | N11: nem | O11: igen | P11: nem | Q11: 0 | S11: Levélírás | T11: Levélírás | U11: Levélírás | V11: Levélírás | W11: Levélírás | Z11: Levélírás | AA11: Levélírás | AB11: Levélírás | AC11: Levélírás | AD11: SZ | AG11: Levélírás | AH11: Levélírás | AI11: Levélírás | AJ11: Levélírás | AK11: Levélírás | AN11: Levélírás | AO11: Levélírás | AP11: Levélírás | AQ11: Levélírás | AR11: Levélírás | AU11: Levélírás | AV11: Levélírás | AW11: =SUM(AX11:BW11)+BZ11 -> 22 | AX11: =COUNTIF($R11:$AV11,AX$3) -> 0 | AY11: =COUNTIF($R11:$AV11,AY$3) -> 0 | AZ11: =COUNTIF($R11:$AV11,AZ$3) -> 0 | BA11: =COUNTIF($R11:$AV11,BA$3) -> 0 | BB11: =COUNTIF($R11:$AV11,BB$3) -> 0 | BC11: =COUNTIF($R11:$AV11,BC$3) -> 0 | BD11: =COUNTIF($R11:$AV11,BD$3) -> 0 | BE11: =COUNTIF($R11:$AV11,BE$3) -> 0 | ... BP11: =COUNTIF($R11:$AV11,BP$3) -> 0 | BQ11: =COUNTIF($R11:$AV11,BQ$3)+COUNTIF($R11:$AV11,"levelezés em") -> 21 | BR11: =COUNTIF($R11:$AV11,BR$3) -> 0 | BS11: =COUNTIF($R11:$AV11,BS$3) -> 0 | BT11: =COUNTIF($R11:$AV11,BT$3) -> 0 | BU11: =COUNTIF($R11:$AV11,BU$3) -> 0 | BV11: =SUM(CA11:CC11) -> 0 | BW11: =COUNTIF($R11:$AV11,BW$3) -> 0 | BX11: =COUNTIF($R11:$AV11,BX$3) -> 0 | BY11: =COUNTIF($R11:$AV11,BY$3) -> 0 | BZ11: =COUNTIF($R11:$AV11,BZ$3) -> 1 | CA11: =COUNTIF($R11:$AV11,CA$3) -> 0 | CB11: =COUNTIF($R11:$AV11,CB$3) -> 0 | CC11: =COUNTIF($R11:$AV11,CC$3) -> 0
A12: =admin_Levelezés!A9 -> Kissné Balsai Emese | B12: =admin_Levelezés!B9 -> SZABÓ ÁGNES | C12: =admin_Levelezés!C9 -> Gyöngyös | D12: =admin_Levelezés!D9 -> ÜGYFÉLLEVELEZÉS | E12: =admin_Levelezés!E9 -> aktív | F12: nem | G12: 0 | H12: nem | I12: igen | J12: nem | K12: igen | L12: nem | M12: nem | N12: nem | O12: nem | P12: igen | Q12: 0 | S12: SZ | T12: SZ | U12: SZ | V12: SZ | W12: SZ | Z12: Külföldi irodák | AA12: Külföldi irodák | AB12: Külföldi irodák | AC12: Külföldi irodák | AD12: Külföldi irodák | AG12: Külföldi irodák | AH12: Külföldi irodák | AI12: Külföldi irodák | AJ12: Külföldi irodák | AK12: E-ÜSZI | AN12: E-ÜSZI | AO12: Külföldi irodák | AP12: Külföldi irodák | AQ12: Külföldi irodák | AR12: Külföldi irodák | AU12: Külföldi irodák | AV12: SZ | AW12: =SUM(AX12:BW12)+BZ12 -> 22 | AX12: =COUNTIF($R12:$AV12,AX$3) -> 0 | AY12: =COUNTIF($R12:$AV12,AY$3) -> 0 | AZ12: =COUNTIF($R12:$AV12,AZ$3) -> 0 | BA12: =COUNTIF($R12:$AV12,BA$3) -> 0 | BB12: =COUNTIF($R12:$AV12,BB$3) -> 0 | BC12: =COUNTIF($R12:$AV12,BC$3) -> 0 | BD12: =COUNTIF($R12:$AV12,BD$3) -> 0 | BE12: =COUNTIF($R12:$AV12,BE$3) -> 0 | ... BP12: =COUNTIF($R12:$AV12,BP$3) -> 14 | BQ12: =COUNTIF($R12:$AV12,BQ$3)+COUNTIF($R12:$AV12,"levelezés em") -> 0 | BR12: =COUNTIF($R12:$AV12,BR$3) -> 0 | BS12: =COUNTIF($R12:$AV12,BS$3) -> 0 | BT12: =COUNTIF($R12:$AV12,BT$3) -> 0 | BU12: =COUNTIF($R12:$AV12,BU$3) -> 0 | BV12: =SUM(CA12:CC12) -> 0 | BW12: =COUNTIF($R12:$AV12,BW$3) -> 0 | BX12: =COUNTIF($R12:$AV12,BX$3) -> 0 | BY12: =COUNTIF($R12:$AV12,BY$3) -> 0 | BZ12: =COUNTIF($R12:$AV12,BZ$3) -> 6 | CA12: =COUNTIF($R12:$AV12,CA$3) -> 0 | CB12: =COUNTIF($R12:$AV12,CB$3) -> 0 | CC12: =COUNTIF($R12:$AV12,CC$3) -> 0
A13: =admin_Levelezés!A10 -> Kapásné Kalo Ildikó | B13: =admin_Levelezés!B10 -> SZABÓ ÁGNES | C13: =admin_Levelezés!C10 -> Gyöngyös | D13: =admin_Levelezés!D10 -> ÜGYFÉLLEVELEZÉS | E13: =admin_Levelezés!E10 -> aktív | F13: nem | G13: 0 | H13: nem | I13: igen | J13: nem | K13: nem | L13: nem | M13: nem | N13: nem | O13: nem | P13: nem | Q13: 0 | S13: Levélírás | T13: Levélírás | U13: Levélírás | V13: Levélírás | W13: Levélírás | Z13: Levélírás | AA13: SZ | AB13: Levélírás | AC13: Levélírás | AD13: Levélírás | AG13: sz | AH13: sz | AI13: sz | AJ13: sz | AK13: sz | AN13: Levélírás | AO13: Levélírás | AP13: Levélírás | AQ13: Levélírás | AR13: Levélírás | AU13: Levélírás | AV13: Levélírás | AW13: =SUM(AX13:BW13)+BZ13 -> 22 | AX13: =COUNTIF($R13:$AV13,AX$3) -> 0 | AY13: =COUNTIF($R13:$AV13,AY$3) -> 0 | AZ13: =COUNTIF($R13:$AV13,AZ$3) -> 0 | BA13: =COUNTIF($R13:$AV13,BA$3) -> 0 | BB13: =COUNTIF($R13:$AV13,BB$3) -> 0 | BC13: =COUNTIF($R13:$AV13,BC$3) -> 0 | BD13: =COUNTIF($R13:$AV13,BD$3) -> 0 | BE13: =COUNTIF($R13:$AV13,BE$3) -> 0 | ... BP13: =COUNTIF($R13:$AV13,BP$3) -> 0 | BQ13: =COUNTIF($R13:$AV13,BQ$3)+COUNTIF($R13:$AV13,"levelezés em") -> 16 | BR13: =COUNTIF($R13:$AV13,BR$3) -> 0 | BS13: =COUNTIF($R13:$AV13,BS$3) -> 0 | BT13: =COUNTIF($R13:$AV13,BT$3) -> 0 | BU13: =COUNTIF($R13:$AV13,BU$3) -> 0 | BV13: =SUM(CA13:CC13) -> 0 | BW13: =COUNTIF($R13:$AV13,BW$3) -> 0 | BX13: =COUNTIF($R13:$AV13,BX$3) -> 0 | BY13: =COUNTIF($R13:$AV13,BY$3) -> 0 | BZ13: =COUNTIF($R13:$AV13,BZ$3) -> 6 | CA13: =COUNTIF($R13:$AV13,CA$3) -> 0 | CB13: =COUNTIF($R13:$AV13,CB$3) -> 0 | CC13: =COUNTIF($R13:$AV13,CC$3) -> 0
A14: =admin_Levelezés!A11 -> Kissné Szabó Tímea | B14: =admin_Levelezés!B11 -> SZABÓ ÁGNES | C14: =admin_Levelezés!C11 -> Gyöngyös | D14: =admin_Levelezés!D11 -> ÜGYFÉLLEVELEZÉS | E14: =admin_Levelezés!E11 -> aktív | F14: nem | G14: 0 | H14: nem | I14: nem | J14: nem | K14: nem | L14: igen | M14: nem | N14: nem | O14: nem | P14: nem | Q14: 0 | S14: Jogsegély levelezés | T14: Jogsegély levelezés | U14: Jogsegély levelezés | V14: Jogsegély levelezés | W14: Jogsegély levelezés | Z14: Jogsegély levelezés | AA14: Jogsegély levelezés | AB14: Jogsegély levelezés | AC14: Jogsegély levelezés | AD14: Jogsegély levelezés | AG14: Jogsegély levelezés | AH14: Jogsegély levelezés | AI14: Jogsegély levelezés | AJ14: Jogsegély levelezés | AK14: Jogsegély levelezés | AN14: Jogsegély levelezés | AO14: Jogsegély levelezés | AP14: Jogsegély levelezés | AQ14: Jogsegély levelezés | AR14: SZ | AU14: Jogsegély levelezés | AV14: Jogsegély levelezés | AW14: =SUM(AX14:BW14)+BZ14 -> 22 | AX14: =COUNTIF($R14:$AV14,AX$3) -> 0 | AY14: =COUNTIF($R14:$AV14,AY$3) -> 0 | AZ14: =COUNTIF($R14:$AV14,AZ$3) -> 0 | BA14: =COUNTIF($R14:$AV14,BA$3) -> 0 | BB14: =COUNTIF($R14:$AV14,BB$3) -> 0 | BC14: =COUNTIF($R14:$AV14,BC$3) -> 0 | BD14: =COUNTIF($R14:$AV14,BD$3) -> 0 | BE14: =COUNTIF($R14:$AV14,BE$3) -> 0 | ... BP14: =COUNTIF($R14:$AV14,BP$3) -> 0 | BQ14: =COUNTIF($R14:$AV14,BQ$3)+COUNTIF($R14:$AV14,"levelezés em") -> 0 | BR14: =COUNTIF($R14:$AV14,BR$3) -> 0 | BS14: =COUNTIF($R14:$AV14,BS$3) -> 0 | BT14: =COUNTIF($R14:$AV14,BT$3) -> 0 | BU14: =COUNTIF($R14:$AV14,BU$3) -> 0 | BV14: =SUM(CA14:CC14) -> 0 | BW14: =COUNTIF($R14:$AV14,BW$3) -> 0 | BX14: =COUNTIF($R14:$AV14,BX$3) -> 0 | BY14: =COUNTIF($R14:$AV14,BY$3) -> 0 | BZ14: =COUNTIF($R14:$AV14,BZ$3) -> 1 | CA14: =COUNTIF($R14:$AV14,CA$3) -> 0 | CB14: =COUNTIF($R14:$AV14,CB$3) -> 0 | CC14: =COUNTIF($R14:$AV14,CC$3) -> 0
A15: =admin_Levelezés!A12 -> Pálfalvi Ferencné | B15: =admin_Levelezés!B12 -> SZABÓ ÁGNES | C15: =admin_Levelezés!C12 -> Gyöngyös | D15: =admin_Levelezés!D12 -> ÜGYFÉLLEVELEZÉS | E15: =admin_Levelezés!E12 -> aktív | F15: nem | G15: 0 | H15: nem | I15: igen | J15: nem | K15: nem | L15: nem | M15: nem | N15: nem | O15: nem | P15: igen | Q15: 0 | S15: Külföldi irodák | T15: Külföldi irodák | U15: Külföldi irodák | V15: Külföldi irodák | W15: Külföldi irodák | Z15: Külföldi irodák | AA15: Külföldi irodák | AB15: Külföldi irodák | AC15: Külföldi irodák | AD15: Külföldi irodák | AG15: Külföldi irodák | AH15: Külföldi irodák | AI15: Külföldi irodák | AJ15: Külföldi irodák | AK15: Külföldi irodák | AN15: Külföldi irodák | AO15: Külföldi irodák | AP15: Külföldi irodák | AQ15: Külföldi irodák | AR15: Külföldi irodák | AU15: Külföldi irodák | AV15: Külföldi irodák | AW15: =SUM(AX15:BW15)+BZ15 -> 22 | AX15: =COUNTIF($R15:$AV15,AX$3) -> 0 | AY15: =COUNTIF($R15:$AV15,AY$3) -> 0 | AZ15: =COUNTIF($R15:$AV15,AZ$3) -> 0 | BA15: =COUNTIF($R15:$AV15,BA$3) -> 0 | BB15: =COUNTIF($R15:$AV15,BB$3) -> 0 | BC15: =COUNTIF($R15:$AV15,BC$3) -> 0 | BD15: =COUNTIF($R15:$AV15,BD$3) -> 0 | BE15: =COUNTIF($R15:$AV15,BE$3) -> 0 | ... BP15: =COUNTIF($R15:$AV15,BP$3) -> 22 | BQ15: =COUNTIF($R15:$AV15,BQ$3)+COUNTIF($R15:$AV15,"levelezés em") -> 0 | BR15: =COUNTIF($R15:$AV15,BR$3) -> 0 | BS15: =COUNTIF($R15:$AV15,BS$3) -> 0 | BT15: =COUNTIF($R15:$AV15,BT$3) -> 0 | BU15: =COUNTIF($R15:$AV15,BU$3) -> 0 | BV15: =SUM(CA15:CC15) -> 0 | BW15: =COUNTIF($R15:$AV15,BW$3) -> 0 | BX15: =COUNTIF($R15:$AV15,BX$3) -> 0 | BY15: =COUNTIF($R15:$AV15,BY$3) -> 0 | BZ15: =COUNTIF($R15:$AV15,BZ$3) -> 0 | CA15: =COUNTIF($R15:$AV15,CA$3) -> 0 | CB15: =COUNTIF($R15:$AV15,CB$3) -> 0 | CC15: =COUNTIF($R15:$AV15,CC$3) -> 0
A16: =admin_Levelezés!A13 -> Prokai Petronella | B16: =admin_Levelezés!B13 -> SZABÓ ÁGNES | C16: =admin_Levelezés!C13 -> Gyöngyös | D16: =admin_Levelezés!D13 -> ÜGYFÉLLEVELEZÉS | E16: =admin_Levelezés!E13 -> aktív | F16: nem | G16: 0 | H16: nem | I16: nem | J16: igen | K16: igen | L16: igen | M16: nem | N16: nem | O16: nem | P16: nem | Q16: 0 | S16: HUGO | T16: HUGO | U16: HUGO | V16: HUGO (@) | W16: HUGO (@) | Z16: HUGO | AA16: HUGO | AB16: HUGO | AC16: HUGO (@) | AD16: HUGO (@) | AG16: HUGO | AH16: HUGO | AI16: HUGO | AJ16: HUGO (@) | AK16: HUGO (@) | AN16: HUGO | AO16: HUGO | AP16: HUGO | AQ16: HUGO (@) | AR16: HUGO (@) | AU16: SZ | AV16: SZ | AW16: =SUM(AX16:BW16)+BZ16 -> 22 | AX16: =COUNTIF($R16:$AV16,AX$3) -> 0 | AY16: =COUNTIF($R16:$AV16,AY$3) -> 0 | AZ16: =COUNTIF($R16:$AV16,AZ$3) -> 0 | BA16: =COUNTIF($R16:$AV16,BA$3) -> 0 | BB16: =COUNTIF($R16:$AV16,BB$3) -> 0 | BC16: =COUNTIF($R16:$AV16,BC$3) -> 0 | BD16: =COUNTIF($R16:$AV16,BD$3) -> 0 | BE16: =COUNTIF($R16:$AV16,BE$3) -> 0 | ... BP16: =COUNTIF($R16:$AV16,BP$3) -> 0 | BQ16: =COUNTIF($R16:$AV16,BQ$3)+COUNTIF($R16:$AV16,"levelezés em") -> 0 | BR16: =COUNTIF($R16:$AV16,BR$3) -> 0 | BS16: =COUNTIF($R16:$AV16,BS$3) -> 0 | BT16: =COUNTIF($R16:$AV16,BT$3) -> 0 | BU16: =COUNTIF($R16:$AV16,BU$3) -> 0 | BV16: =SUM(CA16:CC16) -> 0 | BW16: =COUNTIF($R16:$AV16,BW$3) -> 0 | BX16: =COUNTIF($R16:$AV16,BX$3) -> 0 | BY16: =COUNTIF($R16:$AV16,BY$3) -> 0 | BZ16: =COUNTIF($R16:$AV16,BZ$3) -> 2 | CA16: =COUNTIF($R16:$AV16,CA$3) -> 0 | CB16: =COUNTIF($R16:$AV16,CB$3) -> 0 | CC16: =COUNTIF($R16:$AV16,CC$3) -> 0
