Workbook

Sheet Munka1
A1: Hét | B1: Dátum | C1: Kiküldött levélszám | D1: Outlook beérkező | E1: ÜSZI rögzített hangfájlok száma | F1: Video hívások száma | G1: CC hívások száma | H1: Levelezés megválaszolt | I1: Levelezés feldolgozandó
A2: 1 | B2: 45658 | C2: =_xlfn.IFNA(VLOOKUP(B2,SZO!A:B,2,0),"") -> 0 | D2: =VLOOKUP(B2,[1]Pivot!$A:$B,2,0) -> 86 | E2: =_xlfn.IFNA(VLOOKUP(B2,Nyers!A:E,5,0),"") | F2: =_xlfn.IFNA(VLOOKUP(B2,Nyers!A:F,6,0),"") | G2: =_xlfn.IFNA(VLOOKUP(B2,Nyers!A:H,8,0),"") | H2: =_xlfn.IFNA(VLOOKUP(B2,Nyers!A:D,4,0),"") | I2: =_xlfn.IFNA(VLOOKUP(B2,Nyers!A:G,7,0),"")
A3: 1 | B3: 45659 | C3: =_xlfn.IFNA(VLOOKUP(B3,SZO!A:B,2,0),"") -> 0 | D3: =VLOOKUP(B3,[1]Pivot!$A:$B,2,0) -> 398 | E3: =_xlfn.IFNA(VLOOKUP(B3,Nyers!A:E,5,0),"") -> 537 | F3: =_xlfn.IFNA(VLOOKUP(B3,Nyers!A:F,6,0),"") -> 53 | G3: =_xlfn.IFNA(VLOOKUP(B3,Nyers!A:H,8,0),"") -> 408 | H3: =_xlfn.IFNA(VLOOKUP(B3,Nyers!A:D,4,0),"") -> 523 | I3: =_xlfn.IFNA(VLOOKUP(B3,Nyers!A:G,7,0),"") -> 7775
A4: 2 | B4: 45660 | C4: =_xlfn.IFNA(VLOOKUP(B4,SZO!A:B,2,0),"") -> 5 | D4: =VLOOKUP(B4,[1]Pivot!$A:$B,2,0) -> 349 | E4: =_xlfn.IFNA(VLOOKUP(B4,Nyers!A:E,5,0),"") -> 541 | F4: =_xlfn.IFNA(VLOOKUP(B4,Nyers!A:F,6,0),"") -> 30 | G4: =_xlfn.IFNA(VLOOKUP(B4,Nyers!A:H,8,0),"") -> 413 | H4: =_xlfn.IFNA(VLOOKUP(B4,Nyers!A:D,4,0),"") -> 580 | I4: =_xlfn.IFNA(VLOOKUP(B4,Nyers!A:G,7,0),"") -> 7970
A5: 2 | B5: 45661 | C5: =_xlfn.IFNA(VLOOKUP(B5,SZO!A:B,2,0),"") | D5: =VLOOKUP(B5,[1]Pivot!$A:$B,2,0) -> 99 | E5: =_xlfn.IFNA(VLOOKUP(B5,Nyers!A:E,5,0),"") | F5: =_xlfn.IFNA(VLOOKUP(B5,Nyers!A:F,6,0),"") | G5: =_xlfn.IFNA(VLOOKUP(B5,Nyers!A:H,8,0),"") | H5: =_xlfn.IFNA(VLOOKUP(B5,Nyers!A:D,4,0),"") | I5: =_xlfn.IFNA(VLOOKUP(B5,Nyers!A:G,7,0),"")
A6: 2 | B6: 45662 | C6: =_xlfn.IFNA(VLOOKUP(B6,SZO!A:B,2,0),"") | D6: =VLOOKUP(B6,[1]Pivot!$A:$B,2,0) -> 118 | E6: =_xlfn.IFNA(VLOOKUP(B6,Nyers!A:E,5,0),"") | F6: =_xlfn.IFNA(VLOOKUP(B6,Nyers!A:F,6,0),"") | G6: =_xlfn.IFNA(VLOOKUP(B6,Nyers!A:H,8,0),"") | H6: =_xlfn.IFNA(VLOOKUP(B6,Nyers!A:D,4,0),"") | I6: =_xlfn.IFNA(VLOOKUP(B6,Nyers!A:G,7,0),"")
A7: 2 | B7: 45663 | C7: =_xlfn.IFNA(VLOOKUP(B7,SZO!A:B,2,0),"") -> 0 | D7: =VLOOKUP(B7,[1]Pivot!$A:$B,2,0) -> 565 | E7: =_xlfn.IFNA(VLOOKUP(B7,Nyers!A:E,5,0),"") -> 727 | F7: =_xlfn.IFNA(VLOOKUP(B7,Nyers!A:F,6,0),"") -> 58 | G7: =_xlfn.IFNA(VLOOKUP(B7,Nyers!A:H,8,0),"") -> 737 | H7: =_xlfn.IFNA(VLOOKUP(B7,Nyers!A:D,4,0),"") -> 745 | I7: =_xlfn.IFNA(VLOOKUP(B7,Nyers!A:G,7,0),"") -> 7705
A8: 2 | B8: 45664 | C8: =_xlfn.IFNA(VLOOKUP(B8,SZO!A:B,2,0),"") -> 0 | D8: =VLOOKUP(B8,[1]Pivot!$A:$B,2,0) -> 519 | E8: =_xlfn.IFNA(VLOOKUP(B8,Nyers!A:E,5,0),"") -> 693 | F8: =_xlfn.IFNA(VLOOKUP(B8,Nyers!A:F,6,0),"") -> 52 | G8: =_xlfn.IFNA(VLOOKUP(B8,Nyers!A:H,8,0),"") -> 545 | H8: =_xlfn.IFNA(VLOOKUP(B8,Nyers!A:D,4,0),"") -> 742 | I8: =_xlfn.IFNA(VLOOKUP(B8,Nyers!A:G,7,0),"") -> 7392
A9: 3 | B9: 45665 | C9: =_xlfn.IFNA(VLOOKUP(B9,SZO!A:B,2,0),"") -> 3550 | D9: =VLOOKUP(B9,[1]Pivot!$A:$B,2,0) -> 616 | E9: =_xlfn.IFNA(VLOOKUP(B9,Nyers!A:E,5,0),"") -> 647 | F9: =_xlfn.IFNA(VLOOKUP(B9,Nyers!A:F,6,0),"") -> 68 | G9: =_xlfn.IFNA(VLOOKUP(B9,Nyers!A:H,8,0),"") -> 559 | H9: =_xlfn.IFNA(VLOOKUP(B9,Nyers!A:D,4,0),"") -> 756 | I9: =_xlfn.IFNA(VLOOKUP(B9,Nyers!A:G,7,0),"") -> 7158
A10: 3 | B10: 45666 | C10: =_xlfn.IFNA(VLOOKUP(B10,SZO!A:B,2,0),"") -> 5139 | D10: =VLOOKUP(B10,[1]Pivot!$A:$B,2,0) -> 562 | E10: =_xlfn.IFNA(VLOOKUP(B10,Nyers!A:E,5,0),"") -> 571 | F10: =_xlfn.IFNA(VLOOKUP(B10,Nyers!A:F,6,0),"") -> 47 | G10: =_xlfn.IFNA(VLOOKUP(B10,Nyers!A:H,8,0),"") -> 455 | H10: =_xlfn.IFNA(VLOOKUP(B10,Nyers!A:D,4,0),"") -> 780 | I10: =_xlfn.IFNA(VLOOKUP(B10,Nyers!A:G,7,0),"") -> 6883
A11: 3 | B11: 45667 | C11: =_xlfn.IFNA(VLOOKUP(B11,SZO!A:B,2,0),"") -> 4250 | D11: =VLOOKUP(B11,[1]Pivot!$A:$B,2,0) -> 518 | E11: =_xlfn.IFNA(VLOOKUP(B11,Nyers!A:E,5,0),"") -> 625 | F11: =_xlfn.IFNA(VLOOKUP(B11,Nyers!A:F,6,0),"") -> 49 | G11: =_xlfn.IFNA(VLOOKUP(B11,Nyers!A:H,8,0),"") -> 444 | H11: =_xlfn.IFNA(VLOOKUP(B11,Nyers!A:D,4,0),"") -> 653 | I11: =_xlfn.IFNA(VLOOKUP(B11,Nyers!A:G,7,0),"") -> 6879
A12: 3 | B12: 45668 | C12: =_xlfn.IFNA(VLOOKUP(B12,SZO!A:B,2,0),"") | D12: =VLOOKUP(B12,[1]Pivot!$A:$B,2,0) -> 88 | E12: =_xlfn.IFNA(VLOOKUP(B12,Nyers!A:E,5,0),"") | F12: =_xlfn.IFNA(VLOOKUP(B12,Nyers!A:F,6,0),"") | G12: =_xlfn.IFNA(VLOOKUP(B12,Nyers!A:H,8,0),"") | H12: =_xlfn.IFNA(VLOOKUP(B12,Nyers!A:D,4,0),"") | I12: =_xlfn.IFNA(VLOOKUP(B12,Nyers!A:G,7,0),"")
A13: 3 | B13: 45669 | C13: =_xlfn.IFNA(VLOOKUP(B13,SZO!A:B,2,0),"") | D13: =VLOOKUP(B13,[1]Pivot!$A:$B,2,0) -> 102 | E13: =_xlfn.IFNA(VLOOKUP(B13,Nyers!A:E,5,0),"") | F13: =_xlfn.IFNA(VLOOKUP(B13,Nyers!A:F,6,0),"") | G13: =_xlfn.IFNA(VLOOKUP(B13,Nyers!A:H,8,0),"") | H13: =_xlfn.IFNA(VLOOKUP(B13,Nyers!A:D,4,0),"") | I13: =_xlfn.IFNA(VLOOKUP(B13,Nyers!A:G,7,0),"")
... A188: 39 | B188: 45844 | C188: =_xlfn.IFNA(VLOOKUP(B188,SZO!A:B,2,0),"") | D188: =VLOOKUP(B188,[1]Pivot!$A:$B,2,0) -> 123 | E188: =_xlfn.IFNA(VLOOKUP(B188,Nyers!A:E,5,0),"") | F188: =_xlfn.IFNA(VLOOKUP(B188,Nyers!A:F,6,0),"") | G188: =_xlfn.IFNA(VLOOKUP(B188,Nyers!A:H,8,0),"") | H188: =_xlfn.IFNA(VLOOKUP(B188,Nyers!A:D,4,0),"") | I188: =_xlfn.IFNA(VLOOKUP(B188,Nyers!A:G,7,0),"")
A189: =WEEKNUM(B189) -> 28 | B189: 45845 | C189: =_xlfn.IFNA(VLOOKUP(B189,SZO!A:B,2,0),"") -> 21 | D189: =VLOOKUP(B189,[1]Pivot!$A:$B,2,0) -> 659 | E189: =_xlfn.IFNA(VLOOKUP(B189,Nyers!A:E,5,0),"") -> 513 | F189: =_xlfn.IFNA(VLOOKUP(B189,Nyers!A:F,6,0),"") -> 156 | G189: =_xlfn.IFNA(VLOOKUP(B189,Nyers!A:H,8,0),"") -> 611 | H189: =_xlfn.IFNA(VLOOKUP(B189,Nyers!A:D,4,0),"") -> 658 | I189: =_xlfn.IFNA(VLOOKUP(B189,Nyers!A:G,7,0),"") -> 2526
A190: =WEEKNUM(B190) -> 28 | B190: 45846 | C190: =_xlfn.IFNA(VLOOKUP(B190,SZO!A:B,2,0),"") -> 0 | D190: =VLOOKUP(B190,[1]Pivot!$A:$B,2,0) -> 747 | E190: =_xlfn.IFNA(VLOOKUP(B190,Nyers!A:E,5,0),"") -> 430 | F190: =_xlfn.IFNA(VLOOKUP(B190,Nyers!A:F,6,0),"") -> 123 | G190: =_xlfn.IFNA(VLOOKUP(B190,Nyers!A:H,8,0),"") -> 504 | H190: =_xlfn.IFNA(VLOOKUP(B190,Nyers!A:D,4,0),"") -> 478 | I190: =_xlfn.IFNA(VLOOKUP(B190,Nyers!A:G,7,0),"") -> 2670
A191: =WEEKNUM(B191) -> 28 | B191: 45847 | C191: =_xlfn.IFNA(VLOOKUP(B191,SZO!A:B,2,0),"") -> 0 | D191: =VLOOKUP(B191,[1]Pivot!$A:$B,2,0) -> 724 | E191: =_xlfn.IFNA(VLOOKUP(B191,Nyers!A:E,5,0),"") -> 564 | F191: =_xlfn.IFNA(VLOOKUP(B191,Nyers!A:F,6,0),"") -> 155 | G191: =_xlfn.IFNA(VLOOKUP(B191,Nyers!A:H,8,0),"") -> 540 | H191: =_xlfn.IFNA(VLOOKUP(B191,Nyers!A:D,4,0),"") -> 499 | I191: =_xlfn.IFNA(VLOOKUP(B191,Nyers!A:G,7,0),"") -> 2763
A192: =WEEKNUM(B192) -> 28 | B192: 45848 | C192: =_xlfn.IFNA(VLOOKUP(B192,SZO!A:B,2,0),"") -> 0 | D192: =VLOOKUP(B192,[1]Pivot!$A:$B,2,0) -> 576 | E192: =_xlfn.IFNA(VLOOKUP(B192,Nyers!A:E,5,0),"") -> 450 | F192: =_xlfn.IFNA(VLOOKUP(B192,Nyers!A:F,6,0),"") -> 137 | G192: =_xlfn.IFNA(VLOOKUP(B192,Nyers!A:H,8,0),"") -> 411 | H192: =_xlfn.IFNA(VLOOKUP(B192,Nyers!A:D,4,0),"") -> 430 | I192: =_xlfn.IFNA(VLOOKUP(B192,Nyers!A:G,7,0),"") -> 2938
A193: =WEEKNUM(B193) -> 28 | B193: 45849 | C193: =_xlfn.IFNA(VLOOKUP(B193,SZO!A:B,2,0),"") -> 0 | D193: =VLOOKUP(B193,[1]Pivot!$A:$B,2,0) -> 498 | E193: =_xlfn.IFNA(VLOOKUP(B193,Nyers!A:E,5,0),"") -> 382 | F193: =_xlfn.IFNA(VLOOKUP(B193,Nyers!A:F,6,0),"") -> 178 | G193: =_xlfn.IFNA(VLOOKUP(B193,Nyers!A:H,8,0),"") -> 393 | H193: =_xlfn.IFNA(VLOOKUP(B193,Nyers!A:D,4,0),"") -> 446 | I193: =_xlfn.IFNA(VLOOKUP(B193,Nyers!A:G,7,0),"") -> 3270
A194: =WEEKNUM(B194) -> 28 | B194: 45850 | C194: =_xlfn.IFNA(VLOOKUP(B194,SZO!A:B,2,0),"") | D194: =VLOOKUP(B194,[1]Pivot!$A:$B,2,0) -> 108 | E194: =_xlfn.IFNA(VLOOKUP(B194,Nyers!A:E,5,0),"") | F194: =_xlfn.IFNA(VLOOKUP(B194,Nyers!A:F,6,0),"") | G194: =_xlfn.IFNA(VLOOKUP(B194,Nyers!A:H,8,0),"") | H194: =_xlfn.IFNA(VLOOKUP(B194,Nyers!A:D,4,0),"") | I194: =_xlfn.IFNA(VLOOKUP(B194,Nyers!A:G,7,0),"")
A195: =WEEKNUM(B195) -> 29 | B195: 45851 | C195: =_xlfn.IFNA(VLOOKUP(B195,SZO!A:B,2,0),"") | D195: =VLOOKUP(B195,[1]Pivot!$A:$B,2,0) -> 144 | E195: =_xlfn.IFNA(VLOOKUP(B195,Nyers!A:E,5,0),"") | F195: =_xlfn.IFNA(VLOOKUP(B195,Nyers!A:F,6,0),"") | G195: =_xlfn.IFNA(VLOOKUP(B195,Nyers!A:H,8,0),"") | H195: =_xlfn.IFNA(VLOOKUP(B195,Nyers!A:D,4,0),"") | I195: =_xlfn.IFNA(VLOOKUP(B195,Nyers!A:G,7,0),"")
A196: =WEEKNUM(B196) -> 29 | B196: 45852 | C196: =_xlfn.IFNA(VLOOKUP(B196,SZO!A:B,2,0),"") -> 1 | D196: =VLOOKUP(B196,[1]Pivot!$A:$B,2,0) -> 594 | E196: =_xlfn.IFNA(VLOOKUP(B196,Nyers!A:E,5,0),"") -> 433 | F196: =_xlfn.IFNA(VLOOKUP(B196,Nyers!A:F,6,0),"") -> 139 | G196: =_xlfn.IFNA(VLOOKUP(B196,Nyers!A:H,8,0),"") -> 524 | H196: =_xlfn.IFNA(VLOOKUP(B196,Nyers!A:D,4,0),"") -> 600 | I196: =_xlfn.IFNA(VLOOKUP(B196,Nyers!A:G,7,0),"") -> 3186
A197: =WEEKNUM(B197) -> 29 | B197: 45853 | C197: =_xlfn.IFNA(VLOOKUP(B197,SZO!A:B,2,0),"") -> 0 | D197: =VLOOKUP(B197,[1]Pivot!$A:$B,2,0) -> 626 | E197: =_xlfn.IFNA(VLOOKUP(B197,Nyers!A:E,5,0),"") -> 399 | F197: =_xlfn.IFNA(VLOOKUP(B197,Nyers!A:F,6,0),"") -> 85 | G197: =_xlfn.IFNA(VLOOKUP(B197,Nyers!A:H,8,0),"") -> 375 | H197: =_xlfn.IFNA(VLOOKUP(B197,Nyers!A:D,4,0),"") -> 527 | I197: =_xlfn.IFNA(VLOOKUP(B197,Nyers!A:G,7,0),"") -> 3169
A198: =WEEKNUM(B198) -> 29 | B198: 45854 | C198: =_xlfn.IFNA(VLOOKUP(B198,SZO!A:B,2,0),"") -> 0 | D198: =VLOOKUP(B198,[1]Pivot!$A:$B,2,0) -> 544 | E198: =_xlfn.IFNA(VLOOKUP(B198,Nyers!A:E,5,0),"") -> 488 | F198: =_xlfn.IFNA(VLOOKUP(B198,Nyers!A:F,6,0),"") -> 133 | G198: =_xlfn.IFNA(VLOOKUP(B198,Nyers!A:H,8,0),"") -> 395 | H198: =_xlfn.IFNA(VLOOKUP(B198,Nyers!A:D,4,0),"") -> 532 | I198: =_xlfn.IFNA(VLOOKUP(B198,Nyers!A:G,7,0),"") -> 3069
A199: =WEEKNUM(B199) -> 29 | B199: 45855 | C199: =_xlfn.IFNA(VLOOKUP(B199,SZO!A:B,2,0),"") -> 0 | D199: =VLOOKUP(B199,[1]Pivot!$A:$B,2,0) -> 418 | E199: =_xlfn.IFNA(VLOOKUP(B199,Nyers!A:E,5,0),"") -> 382 | F199: =_xlfn.IFNA(VLOOKUP(B199,Nyers!A:F,6,0),"") -> 87 | G199: =_xlfn.IFNA(VLOOKUP(B199,Nyers!A:H,8,0),"") -> 362 | H199: =_xlfn.IFNA(VLOOKUP(B199,Nyers!A:D,4,0),"") -> 688 | I199: =_xlfn.IFNA(VLOOKUP(B199,Nyers!A:G,7,0),"") -> 2782
A200: =WEEKNUM(B200) -> 29 | B200: 45856 | C200: =_xlfn.IFNA(VLOOKUP(B200,SZO!A:B,2,0),"") -> 0 | D200: =VLOOKUP(B200,[1]Pivot!$A:$B,2,0) -> 423 | E200: =_xlfn.IFNA(VLOOKUP(B200,Nyers!A:E,5,0),"") -> 313 | F200: =_xlfn.IFNA(VLOOKUP(B200,Nyers!A:F,6,0),"") -> 141 | G200: =_xlfn.IFNA(VLOOKUP(B200,Nyers!A:H,8,0),"") -> 368 | H200: =_xlfn.IFNA(VLOOKUP(B200,Nyers!A:D,4,0),"") -> 492 | I200: =_xlfn.IFNA(VLOOKUP(B200,Nyers!A:G,7,0),"") -> 2836
... A243: =WEEKNUM(B243) -> 35 | B243: 45899 | C243: =_xlfn.IFNA(VLOOKUP(B243,SZO!A:B,2,0),"") | D243: =VLOOKUP(B243,[1]Pivot!$A:$B,2,0) -> 122 | E243: =_xlfn.IFNA(VLOOKUP(B243,Nyers!A:E,5,0),"") | F243: =_xlfn.IFNA(VLOOKUP(B243,Nyers!A:F,6,0),"") | G243: =_xlfn.IFNA(VLOOKUP(B243,Nyers!A:H,8,0),"") | H243: =_xlfn.IFNA(VLOOKUP(B243,Nyers!A:D,4,0),"") | I243: =_xlfn.IFNA(VLOOKUP(B243,Nyers!A:G,7,0),"")
A244: =WEEKNUM(B244) -> 36 | B244: 45900 | C244: =_xlfn.IFNA(VLOOKUP(B244,SZO!A:B,2,0),"") | E244: =_xlfn.IFNA(VLOOKUP(B244,Nyers!A:E,5,0),"") | F244: =_xlfn.IFNA(VLOOKUP(B244,Nyers!A:F,6,0),"") | G244: =_xlfn.IFNA(VLOOKUP(B244,Nyers!A:H,8,0),"") | H244: =_xlfn.IFNA(VLOOKUP(B244,Nyers!A:D,4,0),"") | I244: =_xlfn.IFNA(VLOOKUP(B244,Nyers!A:G,7,0),"")
A245: =WEEKNUM(B245) -> 36 | B245: 45901 | C245: =_xlfn.IFNA(VLOOKUP(B245,SZO!A:B,2,0),"") -> 0 | D245: =VLOOKUP(B245,[1]Pivot!$A:$B,2,0) -> 714 | E245: =_xlfn.IFNA(VLOOKUP(B245,Nyers!A:E,5,0),"") -> 452 | F245: =_xlfn.IFNA(VLOOKUP(B245,Nyers!A:F,6,0),"") -> 156 | G245: =_xlfn.IFNA(VLOOKUP(B245,Nyers!A:H,8,0),"") -> 647 | H245: =_xlfn.IFNA(VLOOKUP(B245,Nyers!A:D,4,0),"") -> 581 | I245: =_xlfn.IFNA(VLOOKUP(B245,Nyers!A:G,7,0),"") -> 4936
A246: =WEEKNUM(B246) -> 36 | B246: 45902 | C246: =_xlfn.IFNA(VLOOKUP(B246,SZO!A:B,2,0),"") -> 0 | D246: =VLOOKUP(B246,[1]Pivot!$A:$B,2,0) -> 634 | E246: =_xlfn.IFNA(VLOOKUP(B246,Nyers!A:E,5,0),"") -> 479 | F246: =_xlfn.IFNA(VLOOKUP(B246,Nyers!A:F,6,0),"") -> 162 | G246: =_xlfn.IFNA(VLOOKUP(B246,Nyers!A:H,8,0),"") -> 524 | H246: =_xlfn.IFNA(VLOOKUP(B246,Nyers!A:D,4,0),"") -> 612 | I246: =_xlfn.IFNA(VLOOKUP(B246,Nyers!A:G,7,0),"") -> 4871
A247: =WEEKNUM(B247) -> 36 | B247: 45903 | C247: =_xlfn.IFNA(VLOOKUP(B247,SZO!A:B,2,0),"") -> 2 | D247: =VLOOKUP(B247,[1]Pivot!$A:$B,2,0) -> 592 | E247: =_xlfn.IFNA(VLOOKUP(B247,Nyers!A:E,5,0),"") -> 521 | F247: =_xlfn.IFNA(VLOOKUP(B247,Nyers!A:F,6,0),"") -> 193 | G247: =_xlfn.IFNA(VLOOKUP(B247,Nyers!A:H,8,0),"") -> 552 | H247: =_xlfn.IFNA(VLOOKUP(B247,Nyers!A:D,4,0),"") -> 704 | I247: =_xlfn.IFNA(VLOOKUP(B247,Nyers!A:G,7,0),"") -> 4815
A248: =WEEKNUM(B248) -> 36 | B248: 45904 | C248: =_xlfn.IFNA(VLOOKUP(B248,SZO!A:B,2,0),"") -> 0 | D248: =VLOOKUP(B248,[1]Pivot!$A:$B,2,0) -> 551 | E248: =_xlfn.IFNA(VLOOKUP(B248,Nyers!A:E,5,0),"") -> 406 | F248: =_xlfn.IFNA(VLOOKUP(B248,Nyers!A:F,6,0),"") -> 147 | G248: =_xlfn.IFNA(VLOOKUP(B248,Nyers!A:H,8,0),"") -> 348 | H248: =_xlfn.IFNA(VLOOKUP(B248,Nyers!A:D,4,0),"") -> 684 | I248: =_xlfn.IFNA(VLOOKUP(B248,Nyers!A:G,7,0),"") -> 4458
A249: =WEEKNUM(B249) -> 36 | B249: 45905 | C249: =_xlfn.IFNA(VLOOKUP(B249,SZO!A:B,2,0),"") -> 0 | D249: =VLOOKUP(B249,[1]Pivot!$A:$B,2,0) -> 470 | E249: =_xlfn.IFNA(VLOOKUP(B249,Nyers!A:E,5,0),"") -> 348 | F249: =_xlfn.IFNA(VLOOKUP(B249,Nyers!A:F,6,0),"") -> 146 | G249: =_xlfn.IFNA(VLOOKUP(B249,Nyers!A:H,8,0),"") -> 373 | H249: =_xlfn.IFNA(VLOOKUP(B249,Nyers!A:D,4,0),"") -> 573 | I249: =_xlfn.IFNA(VLOOKUP(B249,Nyers!A:G,7,0),"") -> 4597
A250: =WEEKNUM(B250) -> 36 | B250: 45906 | C250: =_xlfn.IFNA(VLOOKUP(B250,SZO!A:B,2,0),"") | D250: =VLOOKUP(B250,[1]Pivot!$A:$B,2,0) -> 108 | E250: =_xlfn.IFNA(VLOOKUP(B250,Nyers!A:E,5,0),"") | F250: =_xlfn.IFNA(VLOOKUP(B250,Nyers!A:F,6,0),"") | G250: =_xlfn.IFNA(VLOOKUP(B250,Nyers!A:H,8,0),"") | H250: =_xlfn.IFNA(VLOOKUP(B250,Nyers!A:D,4,0),"") | I250: =_xlfn.IFNA(VLOOKUP(B250,Nyers!A:G,7,0),"")
A251: =WEEKNUM(B251) -> 37 | B251: 45907 | C251: =_xlfn.IFNA(VLOOKUP(B251,SZO!A:B,2,0),"") | D251: =VLOOKUP(B251,[1]Pivot!$A:$B,2,0) -> 101 | E251: =_xlfn.IFNA(VLOOKUP(B251,Nyers!A:E,5,0),"") | F251: =_xlfn.IFNA(VLOOKUP(B251,Nyers!A:F,6,0),"") | G251: =_xlfn.IFNA(VLOOKUP(B251,Nyers!A:H,8,0),"") | H251: =_xlfn.IFNA(VLOOKUP(B251,Nyers!A:D,4,0),"") | I251: =_xlfn.IFNA(VLOOKUP(B251,Nyers!A:G,7,0),"")
A252: =WEEKNUM(B252) -> 37 | B252: 45908 | C252: =_xlfn.IFNA(VLOOKUP(B252,SZO!A:B,2,0),"") -> 0 | D252: =VLOOKUP(B252,[1]Pivot!$A:$B,2,0) -> 568 | E252: =_xlfn.IFNA(VLOOKUP(B252,Nyers!A:E,5,0),"") -> 422 | F252: =_xlfn.IFNA(VLOOKUP(B252,Nyers!A:F,6,0),"") -> 128 | G252: =_xlfn.IFNA(VLOOKUP(B252,Nyers!A:H,8,0),"") -> 426 | H252: =_xlfn.IFNA(VLOOKUP(B252,Nyers!A:D,4,0),"") -> 675 | I252: =_xlfn.IFNA(VLOOKUP(B252,Nyers!A:G,7,0),"") -> 4410
A253: =WEEKNUM(B253) -> 37 | B253: 45909 | C253: =_xlfn.IFNA(VLOOKUP(B253,SZO!A:B,2,0),"") -> 0 | D253: =VLOOKUP(B253,[1]Pivot!$A:$B,2,0) -> 547 | E253: =_xlfn.IFNA(VLOOKUP(B253,Nyers!A:E,5,0),"") -> 336 | F253: =_xlfn.IFNA(VLOOKUP(B253,Nyers!A:F,6,0),"") -> 118 | G253: =_xlfn.IFNA(VLOOKUP(B253,Nyers!A:H,8,0),"") -> 401 | H253: =_xlfn.IFNA(VLOOKUP(B253,Nyers!A:D,4,0),"") -> 794 | I253: =_xlfn.IFNA(VLOOKUP(B253,Nyers!A:G,7,0),"") -> 4050
A254: =WEEKNUM(B254) -> 37 | B254: 45910 | C254: =_xlfn.IFNA(VLOOKUP(B254,SZO!A:B,2,0),"") -> 0 | D254: =VLOOKUP(B254,[1]Pivot!$A:$B,2,0) -> 502 | E254: =_xlfn.IFNA(VLOOKUP(B254,Nyers!A:E,5,0),"") -> 437 | F254: =_xlfn.IFNA(VLOOKUP(B254,Nyers!A:F,6,0),"") -> 152 | G254: =_xlfn.IFNA(VLOOKUP(B254,Nyers!A:H,8,0),"") -> 405 | H254: =_xlfn.IFNA(VLOOKUP(B254,Nyers!A:D,4,0),"") -> 846 | I254: =_xlfn.IFNA(VLOOKUP(B254,Nyers!A:G,7,0),"") -> 3664
A255: =WEEKNUM(B255) -> 37 | B255: 45911 | C255: =_xlfn.IFNA(VLOOKUP(B255,SZO!A:B,2,0),"") -> 1493 | D255: =VLOOKUP(B255,[1]Pivot!$A:$B,2,0) -> 450 | E255: =_xlfn.IFNA(VLOOKUP(B255,Nyers!A:E,5,0),"") -> 299 | F255: =_xlfn.IFNA(VLOOKUP(B255,Nyers!A:F,6,0),"") -> 102 | G255: =_xlfn.IFNA(VLOOKUP(B255,Nyers!A:H,8,0),"") -> 318 | H255: =_xlfn.IFNA(VLOOKUP(B255,Nyers!A:D,4,0),"") -> 773 | I255: =_xlfn.IFNA(VLOOKUP(B255,Nyers!A:G,7,0),"") -> 3257
A256: =WEEKNUM(B256) -> 37 | B256: 45912 | C256: =_xlfn.IFNA(VLOOKUP(B256,SZO!A:B,2,0),"") -> 2236 | D256: =VLOOKUP(B256,[1]Pivot!$A:$B,2,0) -> 379 | E256: =_xlfn.IFNA(VLOOKUP(B256,Nyers!A:E,5,0),"") -> 274 | F256: =_xlfn.IFNA(VLOOKUP(B256,Nyers!A:F,6,0),"") -> 127 | G256: =_xlfn.IFNA(VLOOKUP(B256,Nyers!A:H,8,0),"") -> 303 | H256: =_xlfn.IFNA(VLOOKUP(B256,Nyers!A:D,4,0),"") -> 719 | I256: =_xlfn.IFNA(VLOOKUP(B256,Nyers!A:G,7,0),"") -> 3103
...

Sheet Nyers
A1: Ügyintézés | B1: Levelezés Összes iktatandó | C1: Levelezés Összes megválaszolandó | D1: Levelezés Összes megválaszolt | E1: ÜSZI rögzített hangfájlok száma | F1: Video hívások száma | G1: Levelezés Összes levél | H1: CC hívások száma
A2: 45309 | G2: 8079
A3: 45320 | B3: 1188 | C3: 6279 | D3: 553 | E3: 1157 | F3: 26 | G3: 7467
A4: 45321 | B4: 1171 | C4: 6152 | D4: 582 | E4: 1306 | F4: 20 | G4: 7323
A5: 45322 | B5: 1267 | C5: 6099 | D5: 549 | E5: 1415 | F5: 22 | G5: 7366
A6: 45323 | B6: 1173 | C6: 6166 | D6: 529 | E6: 1127 | F6: 31 | G6: 7339
A7: 45324 | B7: 1096 | C7: 6196 | D7: 468 | E7: 927 | F7: 26 | G7: 7292
A8: 45327 | B8: 962 | C8: 6335 | D8: 578 | E8: 722 | F8: 16 | G8: 7297
A9: 45328 | B9: 825 | C9: 6210 | D9: 693 | E9: 622 | F9: 16 | G9: 7035
A10: 45329 | B10: 599 | C10: 6217 | D10: 619 | E10: 630 | F10: 14 | G10: 6816
A11: 45330 | B11: 523 | C11: 6267 | D11: 558 | E11: 591 | F11: 11 | G11: 6790
A12: 45331 | B12: 653 | C12: 5779 | D12: 572 | E12: 628 | F12: 17 | G12: 6432
A13: 45334 | B13: 426 | C13: 5831 | D13: 601 | E13: 616 | F13: 15 | G13: 6257
A14: 45335 | B14: 397 | C14: 5743 | D14: 573 | E14: 500 | F14: 18 | G14: 6140
... A132: 45506 | B132: 179 | C132: 2987 | D132: 492 | E132: 414 | F132: 72 | G132: 3166
A133: 45507 | B133: 194 | C133: 2643 | D133: 571 | E133: 129 | F133: 39 | G133: 2837 | H133: szombati munkanap
A134: 45509 | B134: 186 | C134: 2645 | D134: 483 | E134: 397 | F134: 67 | G134: 2831
A135: 45510 | B135: 206 | C135: 2559 | D135: 485 | E135: 329 | F135: 63 | G135: 2765
A136: 45511 | B136: 162 | C136: 2483 | D136: 492 | E136: 377 | F136: 51 | G136: 2645
A137: 45512 | B137: 222 | C137: 2365 | D137: 452 | E137: 327 | F137: 72 | G137: 2587
A138: 45513 | B138: 267 | C138: 2313 | D138: 402 | E138: 395 | F138: 82 | G138: 2580
A139: 45516 | B139: 319 | C139: 2236 | D139: 412 | E139: 347 | F139: 59 | G139: 2555
A140: 45517 | B140: 322 | C140: 2172 | D140: 422 | E140: 334 | F140: 65 | G140: 2494
A141: 45518 | B141: 277 | C141: 2166 | D141: 404 | E141: 350 | F141: 83 | G141: 2443
A142: 45519 | B142: 321 | C142: 2097 | D142: 385 | E142: 337 | F142: 93 | G142: 2418
A143: 45520 | B143: 432 | C143: 2259 | D143: 312 | E143: 399 | F143: 89 | G143: 2691
A144: 45525 | B144: 348 | C144: 2325 | D144: 358 | E144: 343 | F144: 62 | G144: 2673
A145: 45526 | B145: 261 | C145: 2209 | D145: 408 | E145: 325 | F145: 49 | G145: 2470
... A195: 45596 | B195: 805 | C195: 6404 | D195: 401 | E195: 461 | F195: 129 | G195: 7209
A196: 45597 | B196: Zárva | C196: Zárva | D196: Zárva | E196: Zárva | F196: Zárva | G196: Zárva
A197: 45600 | B197: 973 | C197: 6328 | D197: 615 | E197: 424 | F197: 110 | G197: 7301
A198: 45601 | B198: 983 | C198: 6193 | D198: 741 | E198: 360 | F198: 89 | G198: 7176
A199: 45602 | B199: 1147 | C199: 5869 | D199: 719 | E199: 364 | F199: 79 | G199: 7016
A200: 45603 | B200: 1224 | C200: 5829 | D200: 666 | E200: 357 | F200: 90 | G200: 7053
A201: 45604 | B201: 1392 | C201: 5303 | D201: 646 | E201: 502 | F201: 162 | G201: 6695
A202: 45607 | B202: 1746 | C202: 5227 | D202: 666 | E202: 535 | F202: 129 | G202: 6973
A203: 45608 | B203: 1998 | C203: 5285 | D203: 697 | E203: 479 | F203: 155 | G203: 7283
A204: 45609 | B204: 1956 | C204: 5646 | D204: 570 | E204: 576 | F204: 142 | G204: 7602
A205: 45610 | B205: 2109 | C205: 5652 | D205: 653 | E205: 493 | F205: 100 | G205: 7761
A206: 45611 | B206: 2383 | C206: 5208 | D206: 549 | E206: 546 | F206: 150 | G206: 7591
...

Sheet SZO
A1: 45658 | B1: 0
A2: 45659 | B2: 0
A3: 45660 | B3: 5
A4: 1. | B4: 5
A5: 45663 | B5: 0
A6: 45664 | B6: 0
A7: 45665 | B7: 3550
A8: 45666 | B8: 5139
A9: 45667 | B9: 4250
A10: 2. | B10: 12939
A11: 45670 | B11: 4223
A12: 45671 | B12: 4118
A13: 45672 | B13: 3917
A14: 45673 | B14: 0
A15: 45674 | B15: 4
A16: 3. | B16: 12262
A17: 45677 | B17: 0
A18: 45678 | B18: 0
A19: 45679 | B19: 0
A20: 45680 | B20: 0
A21: 45681 | B21: 6
A22: 4. | B22: 6
A23: 45684 | B23: 0
A24: 45685 | B24: 3484
A25: 45686 | B25: 2223
A26: 45687 | B26: 2398
A27: 45688 | B27: 2472
A28: 5. | B28: 10577
A29: 45691 | B29: 13
A30: 45692 | B30: 0
A31: 45693 | B31: 0
A32: 45694 | B32: 0
A33: 45695 | B33: 0
A34: 6. | B34: 13
A35: 45698 | B35: 0
A36: 45699 | B36: 0
A37: 45700 | B37: 0
A38: 45701 | B38: 0
A39: 45702 | B39: 6607
A40: 7. | B40: 6607
...
